Workbook

Sheet 仕訳帳 
A1: 2026 | B1: 年
E2: 簡 単 仕 訳 帳 | L2: 元帳兼仕訳帳 | P2: 元帳兼精算表
L3: 501 | M3: 502 | N3: 503 | O3: 504 | P3: 505 | Q3: 506 | R3: 507 | S3: 508 | T3: 509 | U3: 510 | V3: 511 | W3: 512 | X3: 513 | Y3: 514 | Z3: 515 | AA3: 516 | AB3: 517 | AC3: 518 | AD3: 519 | AE3: 520 | AF3: 521 | AG3: 522 | AH3: 523 | AI3: 524 | AJ3: 525 | AK3: 526 | AL3: 530 | AM3: 401 | AN3: 402 | AO3: 403 | AP3: 101 | AQ3: 102 | AR3: 103 | AS3: 104 | AT3: 105 | AU3: 106 | AV3: 107 | AW3: 108 | AX3: 109 | AY3: 110 | AZ3: 111 | BA3: 112 | BB3: 113 | BC3: 114 | BD3: 121 | BE3: 122 | BF3: 123 | BG3: 124 | BH3: 125 | BI3: 126 | BJ3: 127 | BK3: 128 | BL3: 201 | BM3: 202 | BN3: 203 | BO3: 204 | BP3: 205 | BQ3: 206 | BR3: 207 | BS3: 208 | BT3: 209 | BU3: 301 | BV3: 302
A4: 伝票№ | B4: 月 | C4: 日 | D4: 摘要 | E4: ｺｰﾄﾞ | F4: 借方科目 | G4: 金額 | H4: ｺｰﾄﾞ2 | I4: 貸方科目 | J4: 金額3 | L4: =IF(L$3="","",IF(ISNA(VLOOKUP(L$3,科目コード表!$C$4:$D$67,2,FALSE)),"該当科目なし",VLOOKUP(L$3,科目コード表!$C$4:$D$67,2,FALSE))) | M4: =IF(M$3="","",IF(ISNA(VLOOKUP(M$3,科目コード表!$C$4:$D$67,2,FALSE)),"該当科目なし",VLOOKUP(M$3,科目コード表!$C$4:$D$67,2,FALSE))) | N4: =IF(N$3="","",IF(ISNA(VLOOKUP(N$3,科目コード表!$C$4:$D$67,2,FALSE)),"該当科目なし",VLOOKUP(N$3,科目コード表!$C$4:$D$67,2,FALSE))) | O4: =IF(O$3="","",IF(ISNA(VLOOKUP(O$3,科目コード表!$C$4:$D$67,2,FALSE)),"該当科目なし",VLOOKUP(O$3,科目コード表!$C$4:$D$67,2,FALSE))) | P4: =IF(P$3="","",IF(ISNA(VLOOKUP(P$3,科目コード表!$C$4:$D$67,2,FALSE)),"該当科目なし",VLOOKUP(P$3,科目コード表!$C$4:$D$67,2,FALSE))) | Q4: =IF(Q$3="","",IF(ISNA(VLOOKUP(Q$3,科目コード表!$C$4:$D$67,2,FALSE)),"該当科目なし",VLOOKUP(Q$3,科目コード表!$C$4:$D$67,2,FALSE))) | R4: =IF(R$3="","",IF(ISNA(VLOOKUP(R$3,科目コード表!$C$4:$D$67,2,FALSE)),"該当科目なし",VLOOKUP(R$3,科目コード表!$C$4:$D$67,2,FALSE))) | S4: =IF(S$3="","",IF(ISNA(VLOOKUP(S$3,科目コード表!$C$4:$D$67,2,FALSE)),"該当科目なし",VLOOKUP(S$3,科目コード表!$C$4:$D$67,2,FALSE))) | ... BV4: =IF(BV$3="","",IF(ISNA(VLOOKUP(BV$3,科目コード表!$C$4:$D$67,2,FALSE)),"該当科目なし",VLOOKUP(BV$3,科目コード表!$C$4:$D$67,2,FALSE)))
B5: 1 | C5: 1 | D5: 前年繰越 現金 | E5: 101 | F5: =IF(E5="","",IF(ISNA(VLOOKUP(E5,科目コード表!$C$4:$D$67,2,FALSE)),"該当科目なし",VLOOKUP(E5,科目コード表!$C$4:$D$67,2,FALSE))) | G5: 1046520 | I5: =IF(H5="","",IF(ISNA(VLOOKUP(H5,科目コード表!$C$4:$D$67,2,FALSE)),"該当科目なし",VLOOKUP(H5,科目コード表!$C$4:$D$67,2,FALSE))) | L5: =IF($E5=L$3,$G5,0)-IF($H5=L$3,$J5,0) | M5: =IF($E5=M$3,$G5,0)-IF($H5=M$3,$J5,0) | N5: =IF($E5=N$3,$G5,0)-IF($H5=N$3,$J5,0) | O5: =IF($E5=O$3,$G5,0)-IF($H5=O$3,$J5,0) | P5: =IF($E5=P$3,$G5,0)-IF($H5=P$3,$J5,0) | Q5: =IF($E5=Q$3,$G5,0)-IF($H5=Q$3,$J5,0) | R5: =IF($E5=R$3,$G5,0)-IF($H5=R$3,$J5,0) | S5: =IF($E5=S$3,$G5,0)-IF($H5=S$3,$J5,0) | ... AL5: =IF($E5=AL$3,$G5,0)-IF($H5=AL$3,$J5,0) | AM5: =-IF($E5=AM$3,$G5,0)+IF($H5=AM$3,$J5,0) | AN5: =-IF($E5=AN$3,$G5,0)+IF($H5=AN$3,$J5,0) | AO5: =-IF($E5=AO$3,$G5,0)+IF($H5=AO$3,$J5,0) | AP5: =IF($E5=AP$3,$G5,0)-IF($H5=AP$3,$J5,0) | AQ5: =IF($E5=AQ$3,$G5,0)-IF($H5=AQ$3,$J5,0) | AR5: =IF($E5=AR$3,$G5,0)-IF($H5=AR$3,$J5,0) | AS5: =IF($E5=AS$3,$G5,0)-IF($H5=AS$3,$J5,0) | AT5: =IF($E5=AT$3,$G5,0)-IF($H5=AT$3,$J5,0) | AU5: =IF($E5=AU$3,$G5,0)-IF($H5=AU$3,$J5,0) | AV5: =IF($E5=AV$3,$G5,0)-IF($H5=AV$3,$J5,0) | AW5: =IF($E5=AW$3,$G5,0)-IF($H5=AW$3,$J5,0) | ... BK5: =IF($E5=BK$3,$G5,0)-IF($H5=BK$3,$J5,0) | BL5: =-IF($E5=BL$3,$G5,0)+IF($H5=BL$3,$J5,0) | BM5: =-IF($E5=BM$3,$G5,0)+IF($H5=BM$3,$J5,0) | BN5: =-IF($E5=BN$3,$G5,0)+IF($H5=BN$3,$J5,0) | BO5: =-IF($E5=BO$3,$G5,0)+IF($H5=BO$3,$J5,0) | BP5: =-IF($E5=BP$3,$G5,0)+IF($H5=BP$3,$J5,0) | BQ5: =-IF($E5=BQ$3,$G5,0)+IF($H5=BQ$3,$J5,0) | BR5: =-IF($E5=BR$3,$G5,0)+IF($H5=BR$3,$J5,0) | BS5: =-IF($E5=BS$3,$G5,0)+IF($H5=BS$3,$J5,0) | BT5: =-IF($E5=BT$3,$G5,0)+IF($H5=BT$3,$J5,0) | BU5: =+G5-J5 | BV5: =-IF($E5=BV$3,$G5,0)+IF($H5=BV$3,$J5,0)
B6: 1 | C6: 1 | D6: 前年繰越 売掛金 | E6: 107 | F6: =IF(E6="","",IF(ISNA(VLOOKUP(E6,科目コード表!$C$4:$D$67,2,FALSE)),"該当科目なし",VLOOKUP(E6,科目コード表!$C$4:$D$67,2,FALSE))) | G6: 1370500 | I6: =IF(H6="","",IF(ISNA(VLOOKUP(H6,科目コード表!$C$4:$D$67,2,FALSE)),"該当科目なし",VLOOKUP(H6,科目コード表!$C$4:$D$67,2,FALSE))) | L6: =IF($E6=L$3,$G6,0)-IF($H6=L$3,$J6,0) | M6: =IF($E6=M$3,$G6,0)-IF($H6=M$3,$J6,0) | N6: =IF($E6=N$3,$G6,0)-IF($H6=N$3,$J6,0) | O6: =IF($E6=O$3,$G6,0)-IF($H6=O$3,$J6,0) | P6: =IF($E6=P$3,$G6,0)-IF($H6=P$3,$J6,0) | Q6: =IF($E6=Q$3,$G6,0)-IF($H6=Q$3,$J6,0) | R6: =IF($E6=R$3,$G6,0)-IF($H6=R$3,$J6,0) | S6: =IF($E6=S$3,$G6,0)-IF($H6=S$3,$J6,0) | ... AL6: =IF($E6=AL$3,$G6,0)-IF($H6=AL$3,$J6,0) | AM6: =-IF($E6=AM$3,$G6,0)+IF($H6=AM$3,$J6,0) | AN6: =-IF($E6=AN$3,$G6,0)+IF($H6=AN$3,$J6,0) | AO6: =-IF($E6=AO$3,$G6,0)+IF($H6=AO$3,$J6,0) | AP6: =IF($E6=AP$3,$G6,0)-IF($H6=AP$3,$J6,0) | AQ6: =IF($E6=AQ$3,$G6,0)-IF($H6=AQ$3,$J6,0) | AR6: =IF($E6=AR$3,$G6,0)-IF($H6=AR$3,$J6,0) | AS6: =IF($E6=AS$3,$G6,0)-IF($H6=AS$3,$J6,0) | AT6: =IF($E6=AT$3,$G6,0)-IF($H6=AT$3,$J6,0) | AU6: =IF($E6=AU$3,$G6,0)-IF($H6=AU$3,$J6,0) | AV6: =IF($E6=AV$3,$G6,0)-IF($H6=AV$3,$J6,0) | AW6: =IF($E6=AW$3,$G6,0)-IF($H6=AW$3,$J6,0) | ... BK6: =IF($E6=BK$3,$G6,0)-IF($H6=BK$3,$J6,0) | BL6: =-IF($E6=BL$3,$G6,0)+IF($H6=BL$3,$J6,0) | BM6: =-IF($E6=BM$3,$G6,0)+IF($H6=BM$3,$J6,0) | BN6: =-IF($E6=BN$3,$G6,0)+IF($H6=BN$3,$J6,0) | BO6: =-IF($E6=BO$3,$G6,0)+IF($H6=BO$3,$J6,0) | BP6: =-IF($E6=BP$3,$G6,0)+IF($H6=BP$3,$J6,0) | BQ6: =-IF($E6=BQ$3,$G6,0)+IF($H6=BQ$3,$J6,0) | BR6: =-IF($E6=BR$3,$G6,0)+IF($H6=BR$3,$J6,0) | BS6: =-IF($E6=BS$3,$G6,0)+IF($H6=BS$3,$J6,0) | BT6: =-IF($E6=BT$3,$G6,0)+IF($H6=BT$3,$J6,0) | BU6: =+G6-J6 | BV6: =-IF($E6=BV$3,$G6,0)+IF($H6=BV$3,$J6,0)
B7: 1 | C7: 1 | D7: 前年繰越 普通預金 | E7: 103 | F7: =IF(E7="","",IF(ISNA(VLOOKUP(E7,科目コード表!$C$4:$D$67,2,FALSE)),"該当科目なし",VLOOKUP(E7,科目コード表!$C$4:$D$67,2,FALSE))) | G7: 10475394 | I7: =IF(H7="","",IF(ISNA(VLOOKUP(H7,科目コード表!$C$4:$D$67,2,FALSE)),"該当科目なし",VLOOKUP(H7,科目コード表!$C$4:$D$67,2,FALSE))) | L7: =IF($E7=L$3,$G7,0)-IF($H7=L$3,$J7,0) | M7: =IF($E7=M$3,$G7,0)-IF($H7=M$3,$J7,0) | N7: =IF($E7=N$3,$G7,0)-IF($H7=N$3,$J7,0) | O7: =IF($E7=O$3,$G7,0)-IF($H7=O$3,$J7,0) | P7: =IF($E7=P$3,$G7,0)-IF($H7=P$3,$J7,0) | Q7: =IF($E7=Q$3,$G7,0)-IF($H7=Q$3,$J7,0) | R7: =IF($E7=R$3,$G7,0)-IF($H7=R$3,$J7,0) | S7: =IF($E7=S$3,$G7,0)-IF($H7=S$3,$J7,0) | ... AL7: =IF($E7=AL$3,$G7,0)-IF($H7=AL$3,$J7,0) | AM7: =-IF($E7=AM$3,$G7,0)+IF($H7=AM$3,$J7,0) | AN7: =-IF($E7=AN$3,$G7,0)+IF($H7=AN$3,$J7,0) | AO7: =-IF($E7=AO$3,$G7,0)+IF($H7=AO$3,$J7,0) | AP7: =IF($E7=AP$3,$G7,0)-IF($H7=AP$3,$J7,0) | AQ7: =IF($E7=AQ$3,$G7,0)-IF($H7=AQ$3,$J7,0) | AR7: =IF($E7=AR$3,$G7,0)-IF($H7=AR$3,$J7,0) | AS7: =IF($E7=AS$3,$G7,0)-IF($H7=AS$3,$J7,0) | AT7: =IF($E7=AT$3,$G7,0)-IF($H7=AT$3,$J7,0) | AU7: =IF($E7=AU$3,$G7,0)-IF($H7=AU$3,$J7,0) | AV7: =IF($E7=AV$3,$G7,0)-IF($H7=AV$3,$J7,0) | AW7: =IF($E7=AW$3,$G7,0)-IF($H7=AW$3,$J7,0) | ... BK7: =IF($E7=BK$3,$G7,0)-IF($H7=BK$3,$J7,0) | BL7: =-IF($E7=BL$3,$G7,0)+IF($H7=BL$3,$J7,0) | BM7: =-IF($E7=BM$3,$G7,0)+IF($H7=BM$3,$J7,0) | BN7: =-IF($E7=BN$3,$G7,0)+IF($H7=BN$3,$J7,0) | BO7: =-IF($E7=BO$3,$G7,0)+IF($H7=BO$3,$J7,0) | BP7: =-IF($E7=BP$3,$G7,0)+IF($H7=BP$3,$J7,0) | BQ7: =-IF($E7=BQ$3,$G7,0)+IF($H7=BQ$3,$J7,0) | BR7: =-IF($E7=BR$3,$G7,0)+IF($H7=BR$3,$J7,0) | BS7: =-IF($E7=BS$3,$G7,0)+IF($H7=BS$3,$J7,0) | BT7: =-IF($E7=BT$3,$G7,0)+IF($H7=BT$3,$J7,0) | BU7: =+G7-J7 | BV7: =-IF($E7=BV$3,$G7,0)+IF($H7=BV$3,$J7,0)
B8: 1 | C8: 1 | D8: 前年繰越 建物 | E8: 121 | F8: =IF(E8="","",IF(ISNA(VLOOKUP(E8,科目コード表!$C$4:$D$67,2,FALSE)),"該当科目なし",VLOOKUP(E8,科目コード表!$C$4:$D$67,2,FALSE))) | G8: 14597430 | I8: =IF(H8="","",IF(ISNA(VLOOKUP(H8,科目コード表!$C$4:$D$67,2,FALSE)),"該当科目なし",VLOOKUP(H8,科目コード表!$C$4:$D$67,2,FALSE))) | L8: =IF($E8=L$3,$G8,0)-IF($H8=L$3,$J8,0) | M8: =IF($E8=M$3,$G8,0)-IF($H8=M$3,$J8,0) | N8: =IF($E8=N$3,$G8,0)-IF($H8=N$3,$J8,0) | O8: =IF($E8=O$3,$G8,0)-IF($H8=O$3,$J8,0) | P8: =IF($E8=P$3,$G8,0)-IF($H8=P$3,$J8,0) | Q8: =IF($E8=Q$3,$G8,0)-IF($H8=Q$3,$J8,0) | R8: =IF($E8=R$3,$G8,0)-IF($H8=R$3,$J8,0) | S8: =IF($E8=S$3,$G8,0)-IF($H8=S$3,$J8,0) | ... AL8: =IF($E8=AL$3,$G8,0)-IF($H8=AL$3,$J8,0) | AM8: =-IF($E8=AM$3,$G8,0)+IF($H8=AM$3,$J8,0) | AN8: =-IF($E8=AN$3,$G8,0)+IF($H8=AN$3,$J8,0) | AO8: =-IF($E8=AO$3,$G8,0)+IF($H8=AO$3,$J8,0) | AP8: =IF($E8=AP$3,$G8,0)-IF($H8=AP$3,$J8,0) | AQ8: =IF($E8=AQ$3,$G8,0)-IF($H8=AQ$3,$J8,0) | AR8: =IF($E8=AR$3,$G8,0)-IF($H8=AR$3,$J8,0) | AS8: =IF($E8=AS$3,$G8,0)-IF($H8=AS$3,$J8,0) | AT8: =IF($E8=AT$3,$G8,0)-IF($H8=AT$3,$J8,0) | AU8: =IF($E8=AU$3,$G8,0)-IF($H8=AU$3,$J8,0) | AV8: =IF($E8=AV$3,$G8,0)-IF($H8=AV$3,$J8,0) | AW8: =IF($E8=AW$3,$G8,0)-IF($H8=AW$3,$J8,0) | ... BK8: =IF($E8=BK$3,$G8,0)-IF($H8=BK$3,$J8,0) | BL8: =-IF($E8=BL$3,$G8,0)+IF($H8=BL$3,$J8,0) | BM8: =-IF($E8=BM$3,$G8,0)+IF($H8=BM$3,$J8,0) | BN8: =-IF($E8=BN$3,$G8,0)+IF($H8=BN$3,$J8,0) | BO8: =-IF($E8=BO$3,$G8,0)+IF($H8=BO$3,$J8,0) | BP8: =-IF($E8=BP$3,$G8,0)+IF($H8=BP$3,$J8,0) | BQ8: =-IF($E8=BQ$3,$G8,0)+IF($H8=BQ$3,$J8,0) | BR8: =-IF($E8=BR$3,$G8,0)+IF($H8=BR$3,$J8,0) | BS8: =-IF($E8=BS$3,$G8,0)+IF($H8=BS$3,$J8,0) | BT8: =-IF($E8=BT$3,$G8,0)+IF($H8=BT$3,$J8,0) | BU8: =+G8-J8 | BV8: =-IF($E8=BV$3,$G8,0)+IF($H8=BV$3,$J8,0)
B9: 1 | C9: 1 | D9: 前年繰越 構築物 | E9: 127 | F9: =IF(E9="","",IF(ISNA(VLOOKUP(E9,科目コード表!$C$4:$D$67,2,FALSE)),"該当科目なし",VLOOKUP(E9,科目コード表!$C$4:$D$67,2,FALSE))) | G9: 1303020 | I9: =IF(H9="","",IF(ISNA(VLOOKUP(H9,科目コード表!$C$4:$D$67,2,FALSE)),"該当科目なし",VLOOKUP(H9,科目コード表!$C$4:$D$67,2,FALSE))) | L9: =IF($E9=L$3,$G9,0)-IF($H9=L$3,$J9,0) | M9: =IF($E9=M$3,$G9,0)-IF($H9=M$3,$J9,0) | N9: =IF($E9=N$3,$G9,0)-IF($H9=N$3,$J9,0) | O9: =IF($E9=O$3,$G9,0)-IF($H9=O$3,$J9,0) | P9: =IF($E9=P$3,$G9,0)-IF($H9=P$3,$J9,0) | Q9: =IF($E9=Q$3,$G9,0)-IF($H9=Q$3,$J9,0) | R9: =IF($E9=R$3,$G9,0)-IF($H9=R$3,$J9,0) | S9: =IF($E9=S$3,$G9,0)-IF($H9=S$3,$J9,0) | ... AL9: =IF($E9=AL$3,$G9,0)-IF($H9=AL$3,$J9,0) | AM9: =-IF($E9=AM$3,$G9,0)+IF($H9=AM$3,$J9,0) | AN9: =-IF($E9=AN$3,$G9,0)+IF($H9=AN$3,$J9,0) | AO9: =-IF($E9=AO$3,$G9,0)+IF($H9=AO$3,$J9,0) | AP9: =IF($E9=AP$3,$G9,0)-IF($H9=AP$3,$J9,0) | AQ9: =IF($E9=AQ$3,$G9,0)-IF($H9=AQ$3,$J9,0) | AR9: =IF($E9=AR$3,$G9,0)-IF($H9=AR$3,$J9,0) | AS9: =IF($E9=AS$3,$G9,0)-IF($H9=AS$3,$J9,0) | AT9: =IF($E9=AT$3,$G9,0)-IF($H9=AT$3,$J9,0) | AU9: =IF($E9=AU$3,$G9,0)-IF($H9=AU$3,$J9,0) | AV9: =IF($E9=AV$3,$G9,0)-IF($H9=AV$3,$J9,0) | AW9: =IF($E9=AW$3,$G9,0)-IF($H9=AW$3,$J9,0) | ... BK9: =IF($E9=BK$3,$G9,0)-IF($H9=BK$3,$J9,0) | BL9: =-IF($E9=BL$3,$G9,0)+IF($H9=BL$3,$J9,0) | BM9: =-IF($E9=BM$3,$G9,0)+IF($H9=BM$3,$J9,0) | BN9: =-IF($E9=BN$3,$G9,0)+IF($H9=BN$3,$J9,0) | BO9: =-IF($E9=BO$3,$G9,0)+IF($H9=BO$3,$J9,0) | BP9: =-IF($E9=BP$3,$G9,0)+IF($H9=BP$3,$J9,0) | BQ9: =-IF($E9=BQ$3,$G9,0)+IF($H9=BQ$3,$J9,0) | BR9: =-IF($E9=BR$3,$G9,0)+IF($H9=BR$3,$J9,0) | BS9: =-IF($E9=BS$3,$G9,0)+IF($H9=BS$3,$J9,0) | BT9: =-IF($E9=BT$3,$G9,0)+IF($H9=BT$3,$J9,0) | BU9: =+G9-J9 | BV9: =-IF($E9=BV$3,$G9,0)+IF($H9=BV$3,$J9,0)
B10: 1 | C10: 1 | D10: 前年繰越 車両運搬具 | E10: 124 | F10: =IF(E10="","",IF(ISNA(VLOOKUP(E10,科目コード表!$C$4:$D$67,2,FALSE)),"該当科目なし",VLOOKUP(E10,科目コード表!$C$4:$D$67,2,FALSE))) | G10: 1 | I10: =IF(H10="","",IF(ISNA(VLOOKUP(H10,科目コード表!$C$4:$D$67,2,FALSE)),"該当科目なし",VLOOKUP(H10,科目コード表!$C$4:$D$67,2,FALSE))) | L10: =IF($E10=L$3,$G10,0)-IF($H10=L$3,$J10,0) | M10: =IF($E10=M$3,$G10,0)-IF($H10=M$3,$J10,0) | N10: =IF($E10=N$3,$G10,0)-IF($H10=N$3,$J10,0) | O10: =IF($E10=O$3,$G10,0)-IF($H10=O$3,$J10,0) | P10: =IF($E10=P$3,$G10,0)-IF($H10=P$3,$J10,0) | Q10: =IF($E10=Q$3,$G10,0)-IF($H10=Q$3,$J10,0) | R10: =IF($E10=R$3,$G10,0)-IF($H10=R$3,$J10,0) | S10: =IF($E10=S$3,$G10,0)-IF($H10=S$3,$J10,0) | ... AL10: =IF($E10=AL$3,$G10,0)-IF($H10=AL$3,$J10,0) | AM10: =-IF($E10=AM$3,$G10,0)+IF($H10=AM$3,$J10,0) | AN10: =-IF($E10=AN$3,$G10,0)+IF($H10=AN$3,$J10,0) | AO10: =-IF($E10=AO$3,$G10,0)+IF($H10=AO$3,$J10,0) | AP10: =IF($E10=AP$3,$G10,0)-IF($H10=AP$3,$J10,0) | AQ10: =IF($E10=AQ$3,$G10,0)-IF($H10=AQ$3,$J10,0) | AR10: =IF($E10=AR$3,$G10,0)-IF($H10=AR$3,$J10,0) | AS10: =IF($E10=AS$3,$G10,0)-IF($H10=AS$3,$J10,0) | AT10: =IF($E10=AT$3,$G10,0)-IF($H10=AT$3,$J10,0) | AU10: =IF($E10=AU$3,$G10,0)-IF($H10=AU$3,$J10,0) | AV10: =IF($E10=AV$3,$G10,0)-IF($H10=AV$3,$J10,0) | AW10: =IF($E10=AW$3,$G10,0)-IF($H10=AW$3,$J10,0) | ... BK10: =IF($E10=BK$3,$G10,0)-IF($H10=BK$3,$J10,0) | BL10: =-IF($E10=BL$3,$G10,0)+IF($H10=BL$3,$J10,0) | BM10: =-IF($E10=BM$3,$G10,0)+IF($H10=BM$3,$J10,0) | BN10: =-IF($E10=BN$3,$G10,0)+IF($H10=BN$3,$J10,0) | BO10: =-IF($E10=BO$3,$G10,0)+IF($H10=BO$3,$J10,0) | BP10: =-IF($E10=BP$3,$G10,0)+IF($H10=BP$3,$J10,0) | BQ10: =-IF($E10=BQ$3,$G10,0)+IF($H10=BQ$3,$J10,0) | BR10: =-IF($E10=BR$3,$G10,0)+IF($H10=BR$3,$J10,0) | BS10: =-IF($E10=BS$3,$G10,0)+IF($H10=BS$3,$J10,0) | BT10: =-IF($E10=BT$3,$G10,0)+IF($H10=BT$3,$J10,0) | BU10: =+G10-J10 | BV10: =-IF($E10=BV$3,$G10,0)+IF($H10=BV$3,$J10,0)
B11: 1 | C11: 1 | D11: 前年繰越 リサイクル預託金 | E11: 114 | F11: =IF(E11="","",IF(ISNA(VLOOKUP(E11,科目コード表!$C$4:$D$67,2,FALSE)),"該当科目なし",VLOOKUP(E11,科目コード表!$C$4:$D$67,2,FALSE))) | G11: 9130 | I11: =IF(H11="","",IF(ISNA(VLOOKUP(H11,科目コード表!$C$4:$D$67,2,FALSE)),"該当科目なし",VLOOKUP(H11,科目コード表!$C$4:$D$67,2,FALSE))) | L11: =IF($E11=L$3,$G11,0)-IF($H11=L$3,$J11,0) | M11: =IF($E11=M$3,$G11,0)-IF($H11=M$3,$J11,0) | N11: =IF($E11=N$3,$G11,0)-IF($H11=N$3,$J11,0) | O11: =IF($E11=O$3,$G11,0)-IF($H11=O$3,$J11,0) | P11: =IF($E11=P$3,$G11,0)-IF($H11=P$3,$J11,0) | Q11: =IF($E11=Q$3,$G11,0)-IF($H11=Q$3,$J11,0) | R11: =IF($E11=R$3,$G11,0)-IF($H11=R$3,$J11,0) | S11: =IF($E11=S$3,$G11,0)-IF($H11=S$3,$J11,0) | ... AL11: =IF($E11=AL$3,$G11,0)-IF($H11=AL$3,$J11,0) | AM11: =-IF($E11=AM$3,$G11,0)+IF($H11=AM$3,$J11,0) | AN11: =-IF($E11=AN$3,$G11,0)+IF($H11=AN$3,$J11,0) | AO11: =-IF($E11=AO$3,$G11,0)+IF($H11=AO$3,$J11,0) | AP11: =IF($E11=AP$3,$G11,0)-IF($H11=AP$3,$J11,0) | AQ11: =IF($E11=AQ$3,$G11,0)-IF($H11=AQ$3,$J11,0) | AR11: =IF($E11=AR$3,$G11,0)-IF($H11=AR$3,$J11,0) | AS11: =IF($E11=AS$3,$G11,0)-IF($H11=AS$3,$J11,0) | AT11: =IF($E11=AT$3,$G11,0)-IF($H11=AT$3,$J11,0) | AU11: =IF($E11=AU$3,$G11,0)-IF($H11=AU$3,$J11,0) | AV11: =IF($E11=AV$3,$G11,0)-IF($H11=AV$3,$J11,0) | AW11: =IF($E11=AW$3,$G11,0)-IF($H11=AW$3,$J11,0) | ... BK11: =IF($E11=BK$3,$G11,0)-IF($H11=BK$3,$J11,0) | BL11: =-IF($E11=BL$3,$G11,0)+IF($H11=BL$3,$J11,0) | BM11: =-IF($E11=BM$3,$G11,0)+IF($H11=BM$3,$J11,0) | BN11: =-IF($E11=BN$3,$G11,0)+IF($H11=BN$3,$J11,0) | BO11: =-IF($E11=BO$3,$G11,0)+IF($H11=BO$3,$J11,0) | BP11: =-IF($E11=BP$3,$G11,0)+IF($H11=BP$3,$J11,0) | BQ11: =-IF($E11=BQ$3,$G11,0)+IF($H11=BQ$3,$J11,0) | BR11: =-IF($E11=BR$3,$G11,0)+IF($H11=BR$3,$J11,0) | BS11: =-IF($E11=BS$3,$G11,0)+IF($H11=BS$3,$J11,0) | BT11: =-IF($E11=BT$3,$G11,0)+IF($H11=BT$3,$J11,0) | BU11: =+G11-J11 | BV11: =-IF($E11=BV$3,$G11,0)+IF($H11=BV$3,$J11,0)
B12: 1 | C12: 1 | D12: 前年繰越 未払金 | F12: =IF(E12="","",IF(ISNA(VLOOKUP(E12,科目コード表!$C$4:$D$67,2,FALSE)),"該当科目なし",VLOOKUP(E12,科目コード表!$C$4:$D$67,2,FALSE))) | H12: 204 | I12: =IF(H12="","",IF(ISNA(VLOOKUP(H12,科目コード表!$C$4:$D$67,2,FALSE)),"該当科目なし",VLOOKUP(H12,科目コード表!$C$4:$D$67,2,FALSE))) | J12: 61327 | L12: =IF($E12=L$3,$G12,0)-IF($H12=L$3,$J12,0) | M12: =IF($E12=M$3,$G12,0)-IF($H12=M$3,$J12,0) | N12: =IF($E12=N$3,$G12,0)-IF($H12=N$3,$J12,0) | O12: =IF($E12=O$3,$G12,0)-IF($H12=O$3,$J12,0) | P12: =IF($E12=P$3,$G12,0)-IF($H12=P$3,$J12,0) | Q12: =IF($E12=Q$3,$G12,0)-IF($H12=Q$3,$J12,0) | R12: =IF($E12=R$3,$G12,0)-IF($H12=R$3,$J12,0) | S12: =IF($E12=S$3,$G12,0)-IF($H12=S$3,$J12,0) | ... AL12: =IF($E12=AL$3,$G12,0)-IF($H12=AL$3,$J12,0) | AM12: =-IF($E12=AM$3,$G12,0)+IF($H12=AM$3,$J12,0) | AN12: =-IF($E12=AN$3,$G12,0)+IF($H12=AN$3,$J12,0) | AO12: =-IF($E12=AO$3,$G12,0)+IF($H12=AO$3,$J12,0) | AP12: =IF($E12=AP$3,$G12,0)-IF($H12=AP$3,$J12,0) | AQ12: =IF($E12=AQ$3,$G12,0)-IF($H12=AQ$3,$J12,0) | AR12: =IF($E12=AR$3,$G12,0)-IF($H12=AR$3,$J12,0) | AS12: =IF($E12=AS$3,$G12,0)-IF($H12=AS$3,$J12,0) | AT12: =IF($E12=AT$3,$G12,0)-IF($H12=AT$3,$J12,0) | AU12: =IF($E12=AU$3,$G12,0)-IF($H12=AU$3,$J12,0) | AV12: =IF($E12=AV$3,$G12,0)-IF($H12=AV$3,$J12,0) | AW12: =IF($E12=AW$3,$G12,0)-IF($H12=AW$3,$J12,0) | ... BK12: =IF($E12=BK$3,$G12,0)-IF($H12=BK$3,$J12,0) | BL12: =-IF($E12=BL$3,$G12,0)+IF($H12=BL$3,$J12,0) | BM12: =-IF($E12=BM$3,$G12,0)+IF($H12=BM$3,$J12,0) | BN12: =-IF($E12=BN$3,$G12,0)+IF($H12=BN$3,$J12,0) | BO12: =-IF($E12=BO$3,$G12,0)+IF($H12=BO$3,$J12,0) | BP12: =-IF($E12=BP$3,$G12,0)+IF($H12=BP$3,$J12,0) | BQ12: =-IF($E12=BQ$3,$G12,0)+IF($H12=BQ$3,$J12,0) | BR12: =-IF($E12=BR$3,$G12,0)+IF($H12=BR$3,$J12,0) | BS12: =-IF($E12=BS$3,$G12,0)+IF($H12=BS$3,$J12,0) | BT12: =-IF($E12=BT$3,$G12,0)+IF($H12=BT$3,$J12,0) | BU12: =+G12-J12 | BV12: =-IF($E12=BV$3,$G12,0)+IF($H12=BV$3,$J12,0)
B13: 1 | C13: 1 | D13: 前年繰越 元入金 | F13: =IF(E13="","",IF(ISNA(VLOOKUP(E13,科目コード表!$C$4:$D$67,2,FALSE)),"該当科目なし",VLOOKUP(E13,科目コード表!$C$4:$D$67,2,FALSE))) | H13: 302 | I13: =IF(H13="","",IF(ISNA(VLOOKUP(H13,科目コード表!$C$4:$D$67,2,FALSE)),"該当科目なし",VLOOKUP(H13,科目コード表!$C$4:$D$67,2,FALSE))) | J13: 25846530 | L13: =IF($E13=L$3,$G13,0)-IF($H13=L$3,$J13,0) | M13: =IF($E13=M$3,$G13,0)-IF($H13=M$3,$J13,0) | N13: =IF($E13=N$3,$G13,0)-IF($H13=N$3,$J13,0) | O13: =IF($E13=O$3,$G13,0)-IF($H13=O$3,$J13,0) | P13: =IF($E13=P$3,$G13,0)-IF($H13=P$3,$J13,0) | Q13: =IF($E13=Q$3,$G13,0)-IF($H13=Q$3,$J13,0) | R13: =IF($E13=R$3,$G13,0)-IF($H13=R$3,$J13,0) | S13: =IF($E13=S$3,$G13,0)-IF($H13=S$3,$J13,0) | ... AL13: =IF($E13=AL$3,$G13,0)-IF($H13=AL$3,$J13,0) | AM13: =-IF($E13=AM$3,$G13,0)+IF($H13=AM$3,$J13,0) | AN13: =-IF($E13=AN$3,$G13,0)+IF($H13=AN$3,$J13,0) | AO13: =-IF($E13=AO$3,$G13,0)+IF($H13=AO$3,$J13,0) | AP13: =IF($E13=AP$3,$G13,0)-IF($H13=AP$3,$J13,0) | AQ13: =IF($E13=AQ$3,$G13,0)-IF($H13=AQ$3,$J13,0) | AR13: =IF($E13=AR$3,$G13,0)-IF($H13=AR$3,$J13,0) | AS13: =IF($E13=AS$3,$G13,0)-IF($H13=AS$3,$J13,0) | AT13: =IF($E13=AT$3,$G13,0)-IF($H13=AT$3,$J13,0) | AU13: =IF($E13=AU$3,$G13,0)-IF($H13=AU$3,$J13,0) | AV13: =IF($E13=AV$3,$G13,0)-IF($H13=AV$3,$J13,0) | AW13: =IF($E13=AW$3,$G13,0)-IF($H13=AW$3,$J13,0) | ... BK13: =IF($E13=BK$3,$G13,0)-IF($H13=BK$3,$J13,0) | BL13: =-IF($E13=BL$3,$G13,0)+IF($H13=BL$3,$J13,0) | BM13: =-IF($E13=BM$3,$G13,0)+IF($H13=BM$3,$J13,0) | BN13: =-IF($E13=BN$3,$G13,0)+IF($H13=BN$3,$J13,0) | BO13: =-IF($E13=BO$3,$G13,0)+IF($H13=BO$3,$J13,0) | BP13: =-IF($E13=BP$3,$G13,0)+IF($H13=BP$3,$J13,0) | BQ13: =-IF($E13=BQ$3,$G13,0)+IF($H13=BQ$3,$J13,0) | BR13: =-IF($E13=BR$3,$G13,0)+IF($H13=BR$3,$J13,0) | BS13: =-IF($E13=BS$3,$G13,0)+IF($H13=BS$3,$J13,0) | BT13: =-IF($E13=BT$3,$G13,0)+IF($H13=BT$3,$J13,0) | BU13: =+G13-J13 | BV13: =-IF($E13=BV$3,$G13,0)+IF($H13=BV$3,$J13,0)
B14: 1 | C14: 1 | D14: 前年繰越 控除前利益 | F14: =IF(E14="","",IF(ISNA(VLOOKUP(E14,科目コード表!$C$4:$D$67,2,FALSE)),"該当科目なし",VLOOKUP(E14,科目コード表!$C$4:$D$67,2,FALSE))) | H14: 302 | I14: =IF(H14="","",IF(ISNA(VLOOKUP(H14,科目コード表!$C$4:$D$67,2,FALSE)),"該当科目なし",VLOOKUP(H14,科目コード表!$C$4:$D$67,2,FALSE))) | J14: 2894138 | L14: =IF($E14=L$3,$G14,0)-IF($H14=L$3,$J14,0) | M14: =IF($E14=M$3,$G14,0)-IF($H14=M$3,$J14,0) | N14: =IF($E14=N$3,$G14,0)-IF($H14=N$3,$J14,0) | O14: =IF($E14=O$3,$G14,0)-IF($H14=O$3,$J14,0) | P14: =IF($E14=P$3,$G14,0)-IF($H14=P$3,$J14,0) | Q14: =IF($E14=Q$3,$G14,0)-IF($H14=Q$3,$J14,0) | R14: =IF($E14=R$3,$G14,0)-IF($H14=R$3,$J14,0) | S14: =IF($E14=S$3,$G14,0)-IF($H14=S$3,$J14,0) | ... AL14: =IF($E14=AL$3,$G14,0)-IF($H14=AL$3,$J14,0) | AM14: =-IF($E14=AM$3,$G14,0)+IF($H14=AM$3,$J14,0) | AN14: =-IF($E14=AN$3,$G14,0)+IF($H14=AN$3,$J14,0) | AO14: =-IF($E14=AO$3,$G14,0)+IF($H14=AO$3,$J14,0) | AP14: =IF($E14=AP$3,$G14,0)-IF($H14=AP$3,$J14,0) | AQ14: =IF($E14=AQ$3,$G14,0)-IF($H14=AQ$3,$J14,0) | AR14: =IF($E14=AR$3,$G14,0)-IF($H14=AR$3,$J14,0) | AS14: =IF($E14=AS$3,$G14,0)-IF($H14=AS$3,$J14,0) | AT14: =IF($E14=AT$3,$G14,0)-IF($H14=AT$3,$J14,0) | AU14: =IF($E14=AU$3,$G14,0)-IF($H14=AU$3,$J14,0) | AV14: =IF($E14=AV$3,$G14,0)-IF($H14=AV$3,$J14,0) | AW14: =IF($E14=AW$3,$G14,0)-IF($H14=AW$3,$J14,0) | ... BK14: =IF($E14=BK$3,$G14,0)-IF($H14=BK$3,$J14,0) | BL14: =-IF($E14=BL$3,$G14,0)+IF($H14=BL$3,$J14,0) | BM14: =-IF($E14=BM$3,$G14,0)+IF($H14=BM$3,$J14,0) | BN14: =-IF($E14=BN$3,$G14,0)+IF($H14=BN$3,$J14,0) | BO14: =-IF($E14=BO$3,$G14,0)+IF($H14=BO$3,$J14,0) | BP14: =-IF($E14=BP$3,$G14,0)+IF($H14=BP$3,$J14,0) | BQ14: =-IF($E14=BQ$3,$G14,0)+IF($H14=BQ$3,$J14,0) | BR14: =-IF($E14=BR$3,$G14,0)+IF($H14=BR$3,$J14,0) | BS14: =-IF($E14=BS$3,$G14,0)+IF($H14=BS$3,$J14,0) | BT14: =-IF($E14=BT$3,$G14,0)+IF($H14=BT$3,$J14,0) | BU14: =+G14-J14 | BV14: =-IF($E14=BV$3,$G14,0)+IF($H14=BV$3,$J14,0)
B15: 1 | C15: 1 | D15: 振り戻し 未払金 | E15: 204 | F15: =IF(E15="","",IF(ISNA(VLOOKUP(E15,科目コード表!$C$4:$D$67,2,FALSE)),"該当科目なし",VLOOKUP(E15,科目コード表!$C$4:$D$67,2,FALSE))) | G15: 61327 | I15: =IF(H15="","",IF(ISNA(VLOOKUP(H15,科目コード表!$C$4:$D$67,2,FALSE)),"該当科目なし",VLOOKUP(H15,科目コード表!$C$4:$D$67,2,FALSE))) | L15: =IF($E15=L$3,$G15,0)-IF($H15=L$3,$J15,0) | M15: =IF($E15=M$3,$G15,0)-IF($H15=M$3,$J15,0) | N15: =IF($E15=N$3,$G15,0)-IF($H15=N$3,$J15,0) | O15: =IF($E15=O$3,$G15,0)-IF($H15=O$3,$J15,0) | P15: =IF($E15=P$3,$G15,0)-IF($H15=P$3,$J15,0) | Q15: =IF($E15=Q$3,$G15,0)-IF($H15=Q$3,$J15,0) | R15: =IF($E15=R$3,$G15,0)-IF($H15=R$3,$J15,0) | S15: =IF($E15=S$3,$G15,0)-IF($H15=S$3,$J15,0) | ... AL15: =IF($E15=AL$3,$G15,0)-IF($H15=AL$3,$J15,0) | AM15: =-IF($E15=AM$3,$G15,0)+IF($H15=AM$3,$J15,0) | AN15: =-IF($E15=AN$3,$G15,0)+IF($H15=AN$3,$J15,0) | AO15: =-IF($E15=AO$3,$G15,0)+IF($H15=AO$3,$J15,0) | AP15: =IF($E15=AP$3,$G15,0)-IF($H15=AP$3,$J15,0) | AQ15: =IF($E15=AQ$3,$G15,0)-IF($H15=AQ$3,$J15,0) | AR15: =IF($E15=AR$3,$G15,0)-IF($H15=AR$3,$J15,0) | AS15: =IF($E15=AS$3,$G15,0)-IF($H15=AS$3,$J15,0) | AT15: =IF($E15=AT$3,$G15,0)-IF($H15=AT$3,$J15,0) | AU15: =IF($E15=AU$3,$G15,0)-IF($H15=AU$3,$J15,0) | AV15: =IF($E15=AV$3,$G15,0)-IF($H15=AV$3,$J15,0) | AW15: =IF($E15=AW$3,$G15,0)-IF($H15=AW$3,$J15,0) | ... BK15: =IF($E15=BK$3,$G15,0)-IF($H15=BK$3,$J15,0) | BL15: =-IF($E15=BL$3,$G15,0)+IF($H15=BL$3,$J15,0) | BM15: =-IF($E15=BM$3,$G15,0)+IF($H15=BM$3,$J15,0) | BN15: =-IF($E15=BN$3,$G15,0)+IF($H15=BN$3,$J15,0) | BO15: =-IF($E15=BO$3,$G15,0)+IF($H15=BO$3,$J15,0) | BP15: =-IF($E15=BP$3,$G15,0)+IF($H15=BP$3,$J15,0) | BQ15: =-IF($E15=BQ$3,$G15,0)+IF($H15=BQ$3,$J15,0) | BR15: =-IF($E15=BR$3,$G15,0)+IF($H15=BR$3,$J15,0) | BS15: =-IF($E15=BS$3,$G15,0)+IF($H15=BS$3,$J15,0) | BT15: =-IF($E15=BT$3,$G15,0)+IF($H15=BT$3,$J15,0) | BU15: =+G15-J15 | BV15: =-IF($E15=BV$3,$G15,0)+IF($H15=BV$3,$J15,0)
B16: 1 | C16: 1 | D16: 現金を事業主へ戻し | F16: =IF(E16="","",IF(ISNA(VLOOKUP(E16,科目コード表!$C$4:$D$67,2,FALSE)),"該当科目なし",VLOOKUP(E16,科目コード表!$C$4:$D$67,2,FALSE))) | H16: 101 | I16: =IF(H16="","",IF(ISNA(VLOOKUP(H16,科目コード表!$C$4:$D$67,2,FALSE)),"該当科目なし",VLOOKUP(H16,科目コード表!$C$4:$D$67,2,FALSE))) | J16: 1046520 | L16: =IF($E16=L$3,$G16,0)-IF($H16=L$3,$J16,0) | M16: =IF($E16=M$3,$G16,0)-IF($H16=M$3,$J16,0) | N16: =IF($E16=N$3,$G16,0)-IF($H16=N$3,$J16,0) | O16: =IF($E16=O$3,$G16,0)-IF($H16=O$3,$J16,0) | P16: =IF($E16=P$3,$G16,0)-IF($H16=P$3,$J16,0) | Q16: =IF($E16=Q$3,$G16,0)-IF($H16=Q$3,$J16,0) | R16: =IF($E16=R$3,$G16,0)-IF($H16=R$3,$J16,0) | S16: =IF($E16=S$3,$G16,0)-IF($H16=S$3,$J16,0) | ... AL16: =IF($E16=AL$3,$G16,0)-IF($H16=AL$3,$J16,0) | AM16: =-IF($E16=AM$3,$G16,0)+IF($H16=AM$3,$J16,0) | AN16: =-IF($E16=AN$3,$G16,0)+IF($H16=AN$3,$J16,0) | AO16: =-IF($E16=AO$3,$G16,0)+IF($H16=AO$3,$J16,0) | AP16: =IF($E16=AP$3,$G16,0)-IF($H16=AP$3,$J16,0) | AQ16: =IF($E16=AQ$3,$G16,0)-IF($H16=AQ$3,$J16,0) | AR16: =IF($E16=AR$3,$G16,0)-IF($H16=AR$3,$J16,0) | AS16: =IF($E16=AS$3,$G16,0)-IF($H16=AS$3,$J16,0) | AT16: =IF($E16=AT$3,$G16,0)-IF($H16=AT$3,$J16,0) | AU16: =IF($E16=AU$3,$G16,0)-IF($H16=AU$3,$J16,0) | AV16: =IF($E16=AV$3,$G16,0)-IF($H16=AV$3,$J16,0) | AW16: =IF($E16=AW$3,$G16,0)-IF($H16=AW$3,$J16,0) | ... BK16: =IF($E16=BK$3,$G16,0)-IF($H16=BK$3,$J16,0) | BL16: =-IF($E16=BL$3,$G16,0)+IF($H16=BL$3,$J16,0) | BM16: =-IF($E16=BM$3,$G16,0)+IF($H16=BM$3,$J16,0) | BN16: =-IF($E16=BN$3,$G16,0)+IF($H16=BN$3,$J16,0) | BO16: =-IF($E16=BO$3,$G16,0)+IF($H16=BO$3,$J16,0) | BP16: =-IF($E16=BP$3,$G16,0)+IF($H16=BP$3,$J16,0) | BQ16: =-IF($E16=BQ$3,$G16,0)+IF($H16=BQ$3,$J16,0) | BR16: =-IF($E16=BR$3,$G16,0)+IF($H16=BR$3,$J16,0) | BS16: =-IF($E16=BS$3,$G16,0)+IF($H16=BS$3,$J16,0) | BT16: =-IF($E16=BT$3,$G16,0)+IF($H16=BT$3,$J16,0) | BU16: =+G16-J16 | BV16: =-IF($E16=BV$3,$G16,0)+IF($H16=BV$3,$J16,0)
B17: 1 | C17: 1 | D17: 普通預金を事業主へ戻し | F17: =IF(E17="","",IF(ISNA(VLOOKUP(E17,科目コード表!$C$4:$D$67,2,FALSE)),"該当科目なし",VLOOKUP(E17,科目コード表!$C$4:$D$67,2,FALSE))) | H17: 103 | I17: =IF(H17="","",IF(ISNA(VLOOKUP(H17,科目コード表!$C$4:$D$67,2,FALSE)),"該当科目なし",VLOOKUP(H17,科目コード表!$C$4:$D$67,2,FALSE))) | J17: 10475394 | L17: =IF($E17=L$3,$G17,0)-IF($H17=L$3,$J17,0) | M17: =IF($E17=M$3,$G17,0)-IF($H17=M$3,$J17,0) | N17: =IF($E17=N$3,$G17,0)-IF($H17=N$3,$J17,0) | O17: =IF($E17=O$3,$G17,0)-IF($H17=O$3,$J17,0) | P17: =IF($E17=P$3,$G17,0)-IF($H17=P$3,$J17,0) | Q17: =IF($E17=Q$3,$G17,0)-IF($H17=Q$3,$J17,0) | R17: =IF($E17=R$3,$G17,0)-IF($H17=R$3,$J17,0) | S17: =IF($E17=S$3,$G17,0)-IF($H17=S$3,$J17,0) | ... AL17: =IF($E17=AL$3,$G17,0)-IF($H17=AL$3,$J17,0) | AM17: =-IF($E17=AM$3,$G17,0)+IF($H17=AM$3,$J17,0) | AN17: =-IF($E17=AN$3,$G17,0)+IF($H17=AN$3,$J17,0) | AO17: =-IF($E17=AO$3,$G17,0)+IF($H17=AO$3,$J17,0) | AP17: =IF($E17=AP$3,$G17,0)-IF($H17=AP$3,$J17,0) | AQ17: =IF($E17=AQ$3,$G17,0)-IF($H17=AQ$3,$J17,0) | AR17: =IF($E17=AR$3,$G17,0)-IF($H17=AR$3,$J17,0) | AS17: =IF($E17=AS$3,$G17,0)-IF($H17=AS$3,$J17,0) | AT17: =IF($E17=AT$3,$G17,0)-IF($H17=AT$3,$J17,0) | AU17: =IF($E17=AU$3,$G17,0)-IF($H17=AU$3,$J17,0) | AV17: =IF($E17=AV$3,$G17,0)-IF($H17=AV$3,$J17,0) | AW17: =IF($E17=AW$3,$G17,0)-IF($H17=AW$3,$J17,0) | ... BK17: =IF($E17=BK$3,$G17,0)-IF($H17=BK$3,$J17,0) | BL17: =-IF($E17=BL$3,$G17,0)+IF($H17=BL$3,$J17,0) | BM17: =-IF($E17=BM$3,$G17,0)+IF($H17=BM$3,$J17,0) | BN17: =-IF($E17=BN$3,$G17,0)+IF($H17=BN$3,$J17,0) | BO17: =-IF($E17=BO$3,$G17,0)+IF($H17=BO$3,$J17,0) | BP17: =-IF($E17=BP$3,$G17,0)+IF($H17=BP$3,$J17,0) | BQ17: =-IF($E17=BQ$3,$G17,0)+IF($H17=BQ$3,$J17,0) | BR17: =-IF($E17=BR$3,$G17,0)+IF($H17=BR$3,$J17,0) | BS17: =-IF($E17=BS$3,$G17,0)+IF($H17=BS$3,$J17,0) | BT17: =-IF($E17=BT$3,$G17,0)+IF($H17=BT$3,$J17,0) | BU17: =+G17-J17 | BV17: =-IF($E17=BV$3,$G17,0)+IF($H17=BV$3,$J17,0)
B18: 1 | C18: 4 | D18: ドア保護フィルム | E18: 523 | F18: =IF(E18="","",IF(ISNA(VLOOKUP(E18,科目コード表!$C$4:$D$67,2,FALSE)),"該当科目なし",VLOOKUP(E18,科目コード表!$C$4:$D$67,2,FALSE))) | G18: 1905 | I18: =IF(H18="","",IF(ISNA(VLOOKUP(H18,科目コード表!$C$4:$D$67,2,FALSE)),"該当科目なし",VLOOKUP(H18,科目コード表!$C$4:$D$67,2,FALSE))) | L18: =IF($E18=L$3,$G18,0)-IF($H18=L$3,$J18,0) | M18: =IF($E18=M$3,$G18,0)-IF($H18=M$3,$J18,0) | N18: =IF($E18=N$3,$G18,0)-IF($H18=N$3,$J18,0) | O18: =IF($E18=O$3,$G18,0)-IF($H18=O$3,$J18,0) | P18: =IF($E18=P$3,$G18,0)-IF($H18=P$3,$J18,0) | Q18: =IF($E18=Q$3,$G18,0)-IF($H18=Q$3,$J18,0) | R18: =IF($E18=R$3,$G18,0)-IF($H18=R$3,$J18,0) | S18: =IF($E18=S$3,$G18,0)-IF($H18=S$3,$J18,0) | ... AL18: =IF($E18=AL$3,$G18,0)-IF($H18=AL$3,$J18,0) | AM18: =-IF($E18=AM$3,$G18,0)+IF($H18=AM$3,$J18,0) | AN18: =-IF($E18=AN$3,$G18,0)+IF($H18=AN$3,$J18,0) | AO18: =-IF($E18=AO$3,$G18,0)+IF($H18=AO$3,$J18,0) | AP18: =IF($E18=AP$3,$G18,0)-IF($H18=AP$3,$J18,0) | AQ18: =IF($E18=AQ$3,$G18,0)-IF($H18=AQ$3,$J18,0) | AR18: =IF($E18=AR$3,$G18,0)-IF($H18=AR$3,$J18,0) | AS18: =IF($E18=AS$3,$G18,0)-IF($H18=AS$3,$J18,0) | AT18: =IF($E18=AT$3,$G18,0)-IF($H18=AT$3,$J18,0) | AU18: =IF($E18=AU$3,$G18,0)-IF($H18=AU$3,$J18,0) | AV18: =IF($E18=AV$3,$G18,0)-IF($H18=AV$3,$J18,0) | AW18: =IF($E18=AW$3,$G18,0)-IF($H18=AW$3,$J18,0) | ... BK18: =IF($E18=BK$3,$G18,0)-IF($H18=BK$3,$J18,0) | BL18: =-IF($E18=BL$3,$G18,0)+IF($H18=BL$3,$J18,0) | BM18: =-IF($E18=BM$3,$G18,0)+IF($H18=BM$3,$J18,0) | BN18: =-IF($E18=BN$3,$G18,0)+IF($H18=BN$3,$J18,0) | BO18: =-IF($E18=BO$3,$G18,0)+IF($H18=BO$3,$J18,0) | BP18: =-IF($E18=BP$3,$G18,0)+IF($H18=BP$3,$J18,0) | BQ18: =-IF($E18=BQ$3,$G18,0)+IF($H18=BQ$3,$J18,0) | BR18: =-IF($E18=BR$3,$G18,0)+IF($H18=BR$3,$J18,0) | BS18: =-IF($E18=BS$3,$G18,0)+IF($H18=BS$3,$J18,0) | BT18: =-IF($E18=BT$3,$G18,0)+IF($H18=BT$3,$J18,0) | BU18: =+G18-J18 | BV18: =-IF($E18=BV$3,$G18,0)+IF($H18=BV$3,$J18,0)
B19: 1 | C19: 4 | D19: ナビ保護フィルム | E19: 523 | F19: =IF(E19="","",IF(ISNA(VLOOKUP(E19,科目コード表!$C$4:$D$67,2,FALSE)),"該当科目なし",VLOOKUP(E19,科目コード表!$C$4:$D$67,2,FALSE))) | G19: 3196 | I19: =IF(H19="","",IF(ISNA(VLOOKUP(H19,科目コード表!$C$4:$D$67,2,FALSE)),"該当科目なし",VLOOKUP(H19,科目コード表!$C$4:$D$67,2,FALSE))) | L19: =IF($E19=L$3,$G19,0)-IF($H19=L$3,$J19,0) | M19: =IF($E19=M$3,$G19,0)-IF($H19=M$3,$J19,0) | N19: =IF($E19=N$3,$G19,0)-IF($H19=N$3,$J19,0) | O19: =IF($E19=O$3,$G19,0)-IF($H19=O$3,$J19,0) | P19: =IF($E19=P$3,$G19,0)-IF($H19=P$3,$J19,0) | Q19: =IF($E19=Q$3,$G19,0)-IF($H19=Q$3,$J19,0) | R19: =IF($E19=R$3,$G19,0)-IF($H19=R$3,$J19,0) | S19: =IF($E19=S$3,$G19,0)-IF($H19=S$3,$J19,0) | ... AL19: =IF($E19=AL$3,$G19,0)-IF($H19=AL$3,$J19,0) | AM19: =-IF($E19=AM$3,$G19,0)+IF($H19=AM$3,$J19,0) | AN19: =-IF($E19=AN$3,$G19,0)+IF($H19=AN$3,$J19,0) | AO19: =-IF($E19=AO$3,$G19,0)+IF($H19=AO$3,$J19,0) | AP19: =IF($E19=AP$3,$G19,0)-IF($H19=AP$3,$J19,0) | AQ19: =IF($E19=AQ$3,$G19,0)-IF($H19=AQ$3,$J19,0) | AR19: =IF($E19=AR$3,$G19,0)-IF($H19=AR$3,$J19,0) | AS19: =IF($E19=AS$3,$G19,0)-IF($H19=AS$3,$J19,0) | AT19: =IF($E19=AT$3,$G19,0)-IF($H19=AT$3,$J19,0) | AU19: =IF($E19=AU$3,$G19,0)-IF($H19=AU$3,$J19,0) | AV19: =IF($E19=AV$3,$G19,0)-IF($H19=AV$3,$J19,0) | AW19: =IF($E19=AW$3,$G19,0)-IF($H19=AW$3,$J19,0) | ... BK19: =IF($E19=BK$3,$G19,0)-IF($H19=BK$3,$J19,0) | BL19: =-IF($E19=BL$3,$G19,0)+IF($H19=BL$3,$J19,0) | BM19: =-IF($E19=BM$3,$G19,0)+IF($H19=BM$3,$J19,0) | BN19: =-IF($E19=BN$3,$G19,0)+IF($H19=BN$3,$J19,0) | BO19: =-IF($E19=BO$3,$G19,0)+IF($H19=BO$3,$J19,0) | BP19: =-IF($E19=BP$3,$G19,0)+IF($H19=BP$3,$J19,0) | BQ19: =-IF($E19=BQ$3,$G19,0)+IF($H19=BQ$3,$J19,0) | BR19: =-IF($E19=BR$3,$G19,0)+IF($H19=BR$3,$J19,0) | BS19: =-IF($E19=BS$3,$G19,0)+IF($H19=BS$3,$J19,0) | BT19: =-IF($E19=BT$3,$G19,0)+IF($H19=BT$3,$J19,0) | BU19: =+G19-J19 | BV19: =-IF($E19=BV$3,$G19,0)+IF($H19=BV$3,$J19,0)
B20: 1 | C20: 4 | D20: ラゲッジマット | E20: 523 | F20: =IF(E20="","",IF(ISNA(VLOOKUP(E20,科目コード表!$C$4:$D$67,2,FALSE)),"該当科目なし",VLOOKUP(E20,科目コード表!$C$4:$D$67,2,FALSE))) | G20: 4122 | I20: =IF(H20="","",IF(ISNA(VLOOKUP(H20,科目コード表!$C$4:$D$67,2,FALSE)),"該当科目なし",VLOOKUP(H20,科目コード表!$C$4:$D$67,2,FALSE))) | L20: =IF($E20=L$3,$G20,0)-IF($H20=L$3,$J20,0) | M20: =IF($E20=M$3,$G20,0)-IF($H20=M$3,$J20,0) | N20: =IF($E20=N$3,$G20,0)-IF($H20=N$3,$J20,0) | O20: =IF($E20=O$3,$G20,0)-IF($H20=O$3,$J20,0) | P20: =IF($E20=P$3,$G20,0)-IF($H20=P$3,$J20,0) | Q20: =IF($E20=Q$3,$G20,0)-IF($H20=Q$3,$J20,0) | R20: =IF($E20=R$3,$G20,0)-IF($H20=R$3,$J20,0) | S20: =IF($E20=S$3,$G20,0)-IF($H20=S$3,$J20,0) | ... AL20: =IF($E20=AL$3,$G20,0)-IF($H20=AL$3,$J20,0) | AM20: =-IF($E20=AM$3,$G20,0)+IF($H20=AM$3,$J20,0) | AN20: =-IF($E20=AN$3,$G20,0)+IF($H20=AN$3,$J20,0) | AO20: =-IF($E20=AO$3,$G20,0)+IF($H20=AO$3,$J20,0) | AP20: =IF($E20=AP$3,$G20,0)-IF($H20=AP$3,$J20,0) | AQ20: =IF($E20=AQ$3,$G20,0)-IF($H20=AQ$3,$J20,0) | AR20: =IF($E20=AR$3,$G20,0)-IF($H20=AR$3,$J20,0) | AS20: =IF($E20=AS$3,$G20,0)-IF($H20=AS$3,$J20,0) | AT20: =IF($E20=AT$3,$G20,0)-IF($H20=AT$3,$J20,0) | AU20: =IF($E20=AU$3,$G20,0)-IF($H20=AU$3,$J20,0) | AV20: =IF($E20=AV$3,$G20,0)-IF($H20=AV$3,$J20,0) | AW20: =IF($E20=AW$3,$G20,0)-IF($H20=AW$3,$J20,0) | ... BK20: =IF($E20=BK$3,$G20,0)-IF($H20=BK$3,$J20,0) | BL20: =-IF($E20=BL$3,$G20,0)+IF($H20=BL$3,$J20,0) | BM20: =-IF($E20=BM$3,$G20,0)+IF($H20=BM$3,$J20,0) | BN20: =-IF($E20=BN$3,$G20,0)+IF($H20=BN$3,$J20,0) | BO20: =-IF($E20=BO$3,$G20,0)+IF($H20=BO$3,$J20,0) | BP20: =-IF($E20=BP$3,$G20,0)+IF($H20=BP$3,$J20,0) | BQ20: =-IF($E20=BQ$3,$G20,0)+IF($H20=BQ$3,$J20,0) | BR20: =-IF($E20=BR$3,$G20,0)+IF($H20=BR$3,$J20,0) | BS20: =-IF($E20=BS$3,$G20,0)+IF($H20=BS$3,$J20,0) | BT20: =-IF($E20=BT$3,$G20,0)+IF($H20=BT$3,$J20,0) | BU20: =+G20-J20 | BV20: =-IF($E20=BV$3,$G20,0)+IF($H20=BV$3,$J20,0)
B21: 1 | C21: 5 | D21: 中尾洋一へ地代振込 | E21: 520 | F21: =IF(E21="","",IF(ISNA(VLOOKUP(E21,科目コード表!$C$4:$D$67,2,FALSE)),"該当科目なし",VLOOKUP(E21,科目コード表!$C$4:$D$67,2,FALSE))) | G21: 20000 | I21: =IF(H21="","",IF(ISNA(VLOOKUP(H21,科目コード表!$C$4:$D$67,2,FALSE)),"該当科目なし",VLOOKUP(H21,科目コード表!$C$4:$D$67,2,FALSE))) | L21: =IF($E21=L$3,$G21,0)-IF($H21=L$3,$J21,0) | M21: =IF($E21=M$3,$G21,0)-IF($H21=M$3,$J21,0) | N21: =IF($E21=N$3,$G21,0)-IF($H21=N$3,$J21,0) | O21: =IF($E21=O$3,$G21,0)-IF($H21=O$3,$J21,0) | P21: =IF($E21=P$3,$G21,0)-IF($H21=P$3,$J21,0) | Q21: =IF($E21=Q$3,$G21,0)-IF($H21=Q$3,$J21,0) | R21: =IF($E21=R$3,$G21,0)-IF($H21=R$3,$J21,0) | S21: =IF($E21=S$3,$G21,0)-IF($H21=S$3,$J21,0) | ... AL21: =IF($E21=AL$3,$G21,0)-IF($H21=AL$3,$J21,0) | AM21: =-IF($E21=AM$3,$G21,0)+IF($H21=AM$3,$J21,0) | AN21: =-IF($E21=AN$3,$G21,0)+IF($H21=AN$3,$J21,0) | AO21: =-IF($E21=AO$3,$G21,0)+IF($H21=AO$3,$J21,0) | AP21: =IF($E21=AP$3,$G21,0)-IF($H21=AP$3,$J21,0) | AQ21: =IF($E21=AQ$3,$G21,0)-IF($H21=AQ$3,$J21,0) | AR21: =IF($E21=AR$3,$G21,0)-IF($H21=AR$3,$J21,0) | AS21: =IF($E21=AS$3,$G21,0)-IF($H21=AS$3,$J21,0) | AT21: =IF($E21=AT$3,$G21,0)-IF($H21=AT$3,$J21,0) | AU21: =IF($E21=AU$3,$G21,0)-IF($H21=AU$3,$J21,0) | AV21: =IF($E21=AV$3,$G21,0)-IF($H21=AV$3,$J21,0) | AW21: =IF($E21=AW$3,$G21,0)-IF($H21=AW$3,$J21,0) | ... BK21: =IF($E21=BK$3,$G21,0)-IF($H21=BK$3,$J21,0) | BL21: =-IF($E21=BL$3,$G21,0)+IF($H21=BL$3,$J21,0) | BM21: =-IF($E21=BM$3,$G21,0)+IF($H21=BM$3,$J21,0) | BN21: =-IF($E21=BN$3,$G21,0)+IF($H21=BN$3,$J21,0) | BO21: =-IF($E21=BO$3,$G21,0)+IF($H21=BO$3,$J21,0) | BP21: =-IF($E21=BP$3,$G21,0)+IF($H21=BP$3,$J21,0) | BQ21: =-IF($E21=BQ$3,$G21,0)+IF($H21=BQ$3,$J21,0) | BR21: =-IF($E21=BR$3,$G21,0)+IF($H21=BR$3,$J21,0) | BS21: =-IF($E21=BS$3,$G21,0)+IF($H21=BS$3,$J21,0) | BT21: =-IF($E21=BT$3,$G21,0)+IF($H21=BT$3,$J21,0) | BU21: =+G21-J21 | BV21: =-IF($E21=BV$3,$G21,0)+IF($H21=BV$3,$J21,0)
B22: 1 | C22: 15 | D22: セレサ川崎 ユーユー入金 | F22: =IF(E22="","",IF(ISNA(VLOOKUP(E22,科目コード表!$C$4:$D$67,2,FALSE)),"該当科目なし",VLOOKUP(E22,科目コード表!$C$4:$D$67,2,FALSE))) | H22: 107 | I22: =IF(H22="","",IF(ISNA(VLOOKUP(H22,科目コード表!$C$4:$D$67,2,FALSE)),"該当科目なし",VLOOKUP(H22,科目コード表!$C$4:$D$67,2,FALSE))) | J22: 100000 | L22: =IF($E22=L$3,$G22,0)-IF($H22=L$3,$J22,0) | M22: =IF($E22=M$3,$G22,0)-IF($H22=M$3,$J22,0) | N22: =IF($E22=N$3,$G22,0)-IF($H22=N$3,$J22,0) | O22: =IF($E22=O$3,$G22,0)-IF($H22=O$3,$J22,0) | P22: =IF($E22=P$3,$G22,0)-IF($H22=P$3,$J22,0) | Q22: =IF($E22=Q$3,$G22,0)-IF($H22=Q$3,$J22,0) | R22: =IF($E22=R$3,$G22,0)-IF($H22=R$3,$J22,0) | S22: =IF($E22=S$3,$G22,0)-IF($H22=S$3,$J22,0) | ... AL22: =IF($E22=AL$3,$G22,0)-IF($H22=AL$3,$J22,0) | AM22: =-IF($E22=AM$3,$G22,0)+IF($H22=AM$3,$J22,0) | AN22: =-IF($E22=AN$3,$G22,0)+IF($H22=AN$3,$J22,0) | AO22: =-IF($E22=AO$3,$G22,0)+IF($H22=AO$3,$J22,0) | AP22: =IF($E22=AP$3,$G22,0)-IF($H22=AP$3,$J22,0) | AQ22: =IF($E22=AQ$3,$G22,0)-IF($H22=AQ$3,$J22,0) | AR22: =IF($E22=AR$3,$G22,0)-IF($H22=AR$3,$J22,0) | AS22: =IF($E22=AS$3,$G22,0)-IF($H22=AS$3,$J22,0) | AT22: =IF($E22=AT$3,$G22,0)-IF($H22=AT$3,$J22,0) | AU22: =IF($E22=AU$3,$G22,0)-IF($H22=AU$3,$J22,0) | AV22: =IF($E22=AV$3,$G22,0)-IF($H22=AV$3,$J22,0) | AW22: =IF($E22=AW$3,$G22,0)-IF($H22=AW$3,$J22,0) | ... BK22: =IF($E22=BK$3,$G22,0)-IF($H22=BK$3,$J22,0) | BL22: =-IF($E22=BL$3,$G22,0)+IF($H22=BL$3,$J22,0) | BM22: =-IF($E22=BM$3,$G22,0)+IF($H22=BM$3,$J22,0) | BN22: =-IF($E22=BN$3,$G22,0)+IF($H22=BN$3,$J22,0) | BO22: =-IF($E22=BO$3,$G22,0)+IF($H22=BO$3,$J22,0) | BP22: =-IF($E22=BP$3,$G22,0)+IF($H22=BP$3,$J22,0) | BQ22: =-IF($E22=BQ$3,$G22,0)+IF($H22=BQ$3,$J22,0) | BR22: =-IF($E22=BR$3,$G22,0)+IF($H22=BR$3,$J22,0) | BS22: =-IF($E22=BS$3,$G22,0)+IF($H22=BS$3,$J22,0) | BT22: =-IF($E22=BT$3,$G22,0)+IF($H22=BT$3,$J22,0) | BU22: =+G22-J22 | BV22: =-IF($E22=BV$3,$G22,0)+IF($H22=BV$3,$J22,0)
B23: 1 | C23: 16 | D23: Kindle Unlimited会費 | E23: 524 | F23: =IF(E23="","",IF(ISNA(VLOOKUP(E23,科目コード表!$C$4:$D$67,2,FALSE)),"該当科目なし",VLOOKUP(E23,科目コード表!$C$4:$D$67,2,FALSE))) | G23: 980 | I23: =IF(H23="","",IF(ISNA(VLOOKUP(H23,科目コード表!$C$4:$D$67,2,FALSE)),"該当科目なし",VLOOKUP(H23,科目コード表!$C$4:$D$67,2,FALSE))) | L23: =IF($E23=L$3,$G23,0)-IF($H23=L$3,$J23,0) | M23: =IF($E23=M$3,$G23,0)-IF($H23=M$3,$J23,0) | N23: =IF($E23=N$3,$G23,0)-IF($H23=N$3,$J23,0) | O23: =IF($E23=O$3,$G23,0)-IF($H23=O$3,$J23,0) | P23: =IF($E23=P$3,$G23,0)-IF($H23=P$3,$J23,0) | Q23: =IF($E23=Q$3,$G23,0)-IF($H23=Q$3,$J23,0) | R23: =IF($E23=R$3,$G23,0)-IF($H23=R$3,$J23,0) | S23: =IF($E23=S$3,$G23,0)-IF($H23=S$3,$J23,0) | ... AL23: =IF($E23=AL$3,$G23,0)-IF($H23=AL$3,$J23,0) | AM23: =-IF($E23=AM$3,$G23,0)+IF($H23=AM$3,$J23,0) | AN23: =-IF($E23=AN$3,$G23,0)+IF($H23=AN$3,$J23,0) | AO23: =-IF($E23=AO$3,$G23,0)+IF($H23=AO$3,$J23,0) | AP23: =IF($E23=AP$3,$G23,0)-IF($H23=AP$3,$J23,0) | AQ23: =IF($E23=AQ$3,$G23,0)-IF($H23=AQ$3,$J23,0) | AR23: =IF($E23=AR$3,$G23,0)-IF($H23=AR$3,$J23,0) | AS23: =IF($E23=AS$3,$G23,0)-IF($H23=AS$3,$J23,0) | AT23: =IF($E23=AT$3,$G23,0)-IF($H23=AT$3,$J23,0) | AU23: =IF($E23=AU$3,$G23,0)-IF($H23=AU$3,$J23,0) | AV23: =IF($E23=AV$3,$G23,0)-IF($H23=AV$3,$J23,0) | AW23: =IF($E23=AW$3,$G23,0)-IF($H23=AW$3,$J23,0) | ... BK23: =IF($E23=BK$3,$G23,0)-IF($H23=BK$3,$J23,0) | BL23: =-IF($E23=BL$3,$G23,0)+IF($H23=BL$3,$J23,0) | BM23: =-IF($E23=BM$3,$G23,0)+IF($H23=BM$3,$J23,0) | BN23: =-IF($E23=BN$3,$G23,0)+IF($H23=BN$3,$J23,0) | BO23: =-IF($E23=BO$3,$G23,0)+IF($H23=BO$3,$J23,0) | BP23: =-IF($E23=BP$3,$G23,0)+IF($H23=BP$3,$J23,0) | BQ23: =-IF($E23=BQ$3,$G23,0)+IF($H23=BQ$3,$J23,0) | BR23: =-IF($E23=BR$3,$G23,0)+IF($H23=BR$3,$J23,0) | BS23: =-IF($E23=BS$3,$G23,0)+IF($H23=BS$3,$J23,0) | BT23: =-IF($E23=BT$3,$G23,0)+IF($H23=BT$3,$J23,0) | BU23: =+G23-J23 | BV23: =-IF($E23=BV$3,$G23,0)+IF($H23=BV$3,$J23,0)
B24: 1 | C24: 17 | D24: デミオを売却 | F24: =IF(E24="","",IF(ISNA(VLOOKUP(E24,科目コード表!$C$4:$D$67,2,FALSE)),"該当科目なし",VLOOKUP(E24,科目コード表!$C$4:$D$67,2,FALSE))) | H24: 124 | I24: =IF(H24="","",IF(ISNA(VLOOKUP(H24,科目コード表!$C$4:$D$67,2,FALSE)),"該当科目なし",VLOOKUP(H24,科目コード表!$C$4:$D$67,2,FALSE))) | J24: 1 | L24: =IF($E24=L$3,$G24,0)-IF($H24=L$3,$J24,0) | M24: =IF($E24=M$3,$G24,0)-IF($H24=M$3,$J24,0) | N24: =IF($E24=N$3,$G24,0)-IF($H24=N$3,$J24,0) | O24: =IF($E24=O$3,$G24,0)-IF($H24=O$3,$J24,0) | P24: =IF($E24=P$3,$G24,0)-IF($H24=P$3,$J24,0) | Q24: =IF($E24=Q$3,$G24,0)-IF($H24=Q$3,$J24,0) | R24: =IF($E24=R$3,$G24,0)-IF($H24=R$3,$J24,0) | S24: =IF($E24=S$3,$G24,0)-IF($H24=S$3,$J24,0) | ... AL24: =IF($E24=AL$3,$G24,0)-IF($H24=AL$3,$J24,0) | AM24: =-IF($E24=AM$3,$G24,0)+IF($H24=AM$3,$J24,0) | AN24: =-IF($E24=AN$3,$G24,0)+IF($H24=AN$3,$J24,0) | AO24: =-IF($E24=AO$3,$G24,0)+IF($H24=AO$3,$J24,0) | AP24: =IF($E24=AP$3,$G24,0)-IF($H24=AP$3,$J24,0) | AQ24: =IF($E24=AQ$3,$G24,0)-IF($H24=AQ$3,$J24,0) | AR24: =IF($E24=AR$3,$G24,0)-IF($H24=AR$3,$J24,0) | AS24: =IF($E24=AS$3,$G24,0)-IF($H24=AS$3,$J24,0) | AT24: =IF($E24=AT$3,$G24,0)-IF($H24=AT$3,$J24,0) | AU24: =IF($E24=AU$3,$G24,0)-IF($H24=AU$3,$J24,0) | AV24: =IF($E24=AV$3,$G24,0)-IF($H24=AV$3,$J24,0) | AW24: =IF($E24=AW$3,$G24,0)-IF($H24=AW$3,$J24,0) | ... BK24: =IF($E24=BK$3,$G24,0)-IF($H24=BK$3,$J24,0) | BL24: =-IF($E24=BL$3,$G24,0)+IF($H24=BL$3,$J24,0) | BM24: =-IF($E24=BM$3,$G24,0)+IF($H24=BM$3,$J24,0) | BN24: =-IF($E24=BN$3,$G24,0)+IF($H24=BN$3,$J24,0) | BO24: =-IF($E24=BO$3,$G24,0)+IF($H24=BO$3,$J24,0) | BP24: =-IF($E24=BP$3,$G24,0)+IF($H24=BP$3,$J24,0) | BQ24: =-IF($E24=BQ$3,$G24,0)+IF($H24=BQ$3,$J24,0) | BR24: =-IF($E24=BR$3,$G24,0)+IF($H24=BR$3,$J24,0) | BS24: =-IF($E24=BS$3,$G24,0)+IF($H24=BS$3,$J24,0) | BT24: =-IF($E24=BT$3,$G24,0)+IF($H24=BT$3,$J24,0) | BU24: =+G24-J24 | BV24: =-IF($E24=BV$3,$G24,0)+IF($H24=BV$3,$J24,0)
B25: 1 | C25: 17 | D25: 固定資産売却益 | F25: =IF(E25="","",IF(ISNA(VLOOKUP(E25,科目コード表!$C$4:$D$67,2,FALSE)),"該当科目なし",VLOOKUP(E25,科目コード表!$C$4:$D$67,2,FALSE))) | H25: 403 | I25: =IF(H25="","",IF(ISNA(VLOOKUP(H25,科目コード表!$C$4:$D$67,2,FALSE)),"該当科目なし",VLOOKUP(H25,科目コード表!$C$4:$D$67,2,FALSE))) | J25: 329999 | L25: =IF($E25=L$3,$G25,0)-IF($H25=L$3,$J25,0) | M25: =IF($E25=M$3,$G25,0)-IF($H25=M$3,$J25,0) | N25: =IF($E25=N$3,$G25,0)-IF($H25=N$3,$J25,0) | O25: =IF($E25=O$3,$G25,0)-IF($H25=O$3,$J25,0) | P25: =IF($E25=P$3,$G25,0)-IF($H25=P$3,$J25,0) | Q25: =IF($E25=Q$3,$G25,0)-IF($H25=Q$3,$J25,0) | R25: =IF($E25=R$3,$G25,0)-IF($H25=R$3,$J25,0) | S25: =IF($E25=S$3,$G25,0)-IF($H25=S$3,$J25,0) | ... AL25: =IF($E25=AL$3,$G25,0)-IF($H25=AL$3,$J25,0) | AM25: =-IF($E25=AM$3,$G25,0)+IF($H25=AM$3,$J25,0) | AN25: =-IF($E25=AN$3,$G25,0)+IF($H25=AN$3,$J25,0) | AO25: =-IF($E25=AO$3,$G25,0)+IF($H25=AO$3,$J25,0) | AP25: =IF($E25=AP$3,$G25,0)-IF($H25=AP$3,$J25,0) | AQ25: =IF($E25=AQ$3,$G25,0)-IF($H25=AQ$3,$J25,0) | AR25: =IF($E25=AR$3,$G25,0)-IF($H25=AR$3,$J25,0) | AS25: =IF($E25=AS$3,$G25,0)-IF($H25=AS$3,$J25,0) | AT25: =IF($E25=AT$3,$G25,0)-IF($H25=AT$3,$J25,0) | AU25: =IF($E25=AU$3,$G25,0)-IF($H25=AU$3,$J25,0) | AV25: =IF($E25=AV$3,$G25,0)-IF($H25=AV$3,$J25,0) | AW25: =IF($E25=AW$3,$G25,0)-IF($H25=AW$3,$J25,0) | ... BK25: =IF($E25=BK$3,$G25,0)-IF($H25=BK$3,$J25,0) | BL25: =-IF($E25=BL$3,$G25,0)+IF($H25=BL$3,$J25,0) | BM25: =-IF($E25=BM$3,$G25,0)+IF($H25=BM$3,$J25,0) | BN25: =-IF($E25=BN$3,$G25,0)+IF($H25=BN$3,$J25,0) | BO25: =-IF($E25=BO$3,$G25,0)+IF($H25=BO$3,$J25,0) | BP25: =-IF($E25=BP$3,$G25,0)+IF($H25=BP$3,$J25,0) | BQ25: =-IF($E25=BQ$3,$G25,0)+IF($H25=BQ$3,$J25,0) | BR25: =-IF($E25=BR$3,$G25,0)+IF($H25=BR$3,$J25,0) | BS25: =-IF($E25=BS$3,$G25,0)+IF($H25=BS$3,$J25,0) | BT25: =-IF($E25=BT$3,$G25,0)+IF($H25=BT$3,$J25,0) | BU25: =+G25-J25 | BV25: =-IF($E25=BV$3,$G25,0)+IF($H25=BV$3,$J25,0)
B26: 1 | C26: 17 | D26: リサイクル預託金 | F26: =IF(E26="","",IF(ISNA(VLOOKUP(E26,科目コード表!$C$4:$D$67,2,FALSE)),"該当科目なし",VLOOKUP(E26,科目コード表!$C$4:$D$67,2,FALSE))) | H26: 114 | I26: =IF(H26="","",IF(ISNA(VLOOKUP(H26,科目コード表!$C$4:$D$67,2,FALSE)),"該当科目なし",VLOOKUP(H26,科目コード表!$C$4:$D$67,2,FALSE))) | J26: 9130 | L26: =IF($E26=L$3,$G26,0)-IF($H26=L$3,$J26,0) | M26: =IF($E26=M$3,$G26,0)-IF($H26=M$3,$J26,0) | N26: =IF($E26=N$3,$G26,0)-IF($H26=N$3,$J26,0) | O26: =IF($E26=O$3,$G26,0)-IF($H26=O$3,$J26,0) | P26: =IF($E26=P$3,$G26,0)-IF($H26=P$3,$J26,0) | Q26: =IF($E26=Q$3,$G26,0)-IF($H26=Q$3,$J26,0) | R26: =IF($E26=R$3,$G26,0)-IF($H26=R$3,$J26,0) | S26: =IF($E26=S$3,$G26,0)-IF($H26=S$3,$J26,0) | ... AL26: =IF($E26=AL$3,$G26,0)-IF($H26=AL$3,$J26,0) | AM26: =-IF($E26=AM$3,$G26,0)+IF($H26=AM$3,$J26,0) | AN26: =-IF($E26=AN$3,$G26,0)+IF($H26=AN$3,$J26,0) | AO26: =-IF($E26=AO$3,$G26,0)+IF($H26=AO$3,$J26,0) | AP26: =IF($E26=AP$3,$G26,0)-IF($H26=AP$3,$J26,0) | AQ26: =IF($E26=AQ$3,$G26,0)-IF($H26=AQ$3,$J26,0) | AR26: =IF($E26=AR$3,$G26,0)-IF($H26=AR$3,$J26,0) | AS26: =IF($E26=AS$3,$G26,0)-IF($H26=AS$3,$J26,0) | AT26: =IF($E26=AT$3,$G26,0)-IF($H26=AT$3,$J26,0) | AU26: =IF($E26=AU$3,$G26,0)-IF($H26=AU$3,$J26,0) | AV26: =IF($E26=AV$3,$G26,0)-IF($H26=AV$3,$J26,0) | AW26: =IF($E26=AW$3,$G26,0)-IF($H26=AW$3,$J26,0) | ... BK26: =IF($E26=BK$3,$G26,0)-IF($H26=BK$3,$J26,0) | BL26: =-IF($E26=BL$3,$G26,0)+IF($H26=BL$3,$J26,0) | BM26: =-IF($E26=BM$3,$G26,0)+IF($H26=BM$3,$J26,0) | BN26: =-IF($E26=BN$3,$G26,0)+IF($H26=BN$3,$J26,0) | BO26: =-IF($E26=BO$3,$G26,0)+IF($H26=BO$3,$J26,0) | BP26: =-IF($E26=BP$3,$G26,0)+IF($H26=BP$3,$J26,0) | BQ26: =-IF($E26=BQ$3,$G26,0)+IF($H26=BQ$3,$J26,0) | BR26: =-IF($E26=BR$3,$G26,0)+IF($H26=BR$3,$J26,0) | BS26: =-IF($E26=BS$3,$G26,0)+IF($H26=BS$3,$J26,0) | BT26: =-IF($E26=BT$3,$G26,0)+IF($H26=BT$3,$J26,0) | BU26: =+G26-J26 | BV26: =-IF($E26=BV$3,$G26,0)+IF($H26=BV$3,$J26,0)
B27: 1 | C27: 17 | D27: シエンタ(車両)購入 | E27: 124 | F27: =IF(E27="","",IF(ISNA(VLOOKUP(E27,科目コード表!$C$4:$D$67,2,FALSE)),"該当科目なし",VLOOKUP(E27,科目コード表!$C$4:$D$67,2,FALSE))) | G27: 3057480 | I27: =IF(H27="","",IF(ISNA(VLOOKUP(H27,科目コード表!$C$4:$D$67,2,FALSE)),"該当科目なし",VLOOKUP(H27,科目コード表!$C$4:$D$67,2,FALSE))) | L27: =IF($E27=L$3,$G27,0)-IF($H27=L$3,$J27,0) | M27: =IF($E27=M$3,$G27,0)-IF($H27=M$3,$J27,0) | N27: =IF($E27=N$3,$G27,0)-IF($H27=N$3,$J27,0) | O27: =IF($E27=O$3,$G27,0)-IF($H27=O$3,$J27,0) | P27: =IF($E27=P$3,$G27,0)-IF($H27=P$3,$J27,0) | Q27: =IF($E27=Q$3,$G27,0)-IF($H27=Q$3,$J27,0) | R27: =IF($E27=R$3,$G27,0)-IF($H27=R$3,$J27,0) | S27: =IF($E27=S$3,$G27,0)-IF($H27=S$3,$J27,0) | ... AL27: =IF($E27=AL$3,$G27,0)-IF($H27=AL$3,$J27,0) | AM27: =-IF($E27=AM$3,$G27,0)+IF($H27=AM$3,$J27,0) | AN27: =-IF($E27=AN$3,$G27,0)+IF($H27=AN$3,$J27,0) | AO27: =-IF($E27=AO$3,$G27,0)+IF($H27=AO$3,$J27,0) | AP27: =IF($E27=AP$3,$G27,0)-IF($H27=AP$3,$J27,0) | AQ27: =IF($E27=AQ$3,$G27,0)-IF($H27=AQ$3,$J27,0) | AR27: =IF($E27=AR$3,$G27,0)-IF($H27=AR$3,$J27,0) | AS27: =IF($E27=AS$3,$G27,0)-IF($H27=AS$3,$J27,0) | AT27: =IF($E27=AT$3,$G27,0)-IF($H27=AT$3,$J27,0) | AU27: =IF($E27=AU$3,$G27,0)-IF($H27=AU$3,$J27,0) | AV27: =IF($E27=AV$3,$G27,0)-IF($H27=AV$3,$J27,0) | AW27: =IF($E27=AW$3,$G27,0)-IF($H27=AW$3,$J27,0) | ... BK27: =IF($E27=BK$3,$G27,0)-IF($H27=BK$3,$J27,0) | BL27: =-IF($E27=BL$3,$G27,0)+IF($H27=BL$3,$J27,0) | BM27: =-IF($E27=BM$3,$G27,0)+IF($H27=BM$3,$J27,0) | BN27: =-IF($E27=BN$3,$G27,0)+IF($H27=BN$3,$J27,0) | BO27: =-IF($E27=BO$3,$G27,0)+IF($H27=BO$3,$J27,0) | BP27: =-IF($E27=BP$3,$G27,0)+IF($H27=BP$3,$J27,0) | BQ27: =-IF($E27=BQ$3,$G27,0)+IF($H27=BQ$3,$J27,0) | BR27: =-IF($E27=BR$3,$G27,0)+IF($H27=BR$3,$J27,0) | BS27: =-IF($E27=BS$3,$G27,0)+IF($H27=BS$3,$J27,0) | BT27: =-IF($E27=BT$3,$G27,0)+IF($H27=BT$3,$J27,0) | BU27: =+G27-J27 | BV27: =-IF($E27=BV$3,$G27,0)+IF($H27=BV$3,$J27,0)
B28: 1 | C28: 17 | D28: シエンタのリサイクル預託金 | E28: 114 | F28: =IF(E28="","",IF(ISNA(VLOOKUP(E28,科目コード表!$C$4:$D$67,2,FALSE)),"該当科目なし",VLOOKUP(E28,科目コード表!$C$4:$D$67,2,FALSE))) | G28: 11650 | I28: =IF(H28="","",IF(ISNA(VLOOKUP(H28,科目コード表!$C$4:$D$67,2,FALSE)),"該当科目なし",VLOOKUP(H28,科目コード表!$C$4:$D$67,2,FALSE))) | L28: =IF($E28=L$3,$G28,0)-IF($H28=L$3,$J28,0) | M28: =IF($E28=M$3,$G28,0)-IF($H28=M$3,$J28,0) | N28: =IF($E28=N$3,$G28,0)-IF($H28=N$3,$J28,0) | O28: =IF($E28=O$3,$G28,0)-IF($H28=O$3,$J28,0) | P28: =IF($E28=P$3,$G28,0)-IF($H28=P$3,$J28,0) | Q28: =IF($E28=Q$3,$G28,0)-IF($H28=Q$3,$J28,0) | R28: =IF($E28=R$3,$G28,0)-IF($H28=R$3,$J28,0) | S28: =IF($E28=S$3,$G28,0)-IF($H28=S$3,$J28,0) | ... AL28: =IF($E28=AL$3,$G28,0)-IF($H28=AL$3,$J28,0) | AM28: =-IF($E28=AM$3,$G28,0)+IF($H28=AM$3,$J28,0) | AN28: =-IF($E28=AN$3,$G28,0)+IF($H28=AN$3,$J28,0) | AO28: =-IF($E28=AO$3,$G28,0)+IF($H28=AO$3,$J28,0) | AP28: =IF($E28=AP$3,$G28,0)-IF($H28=AP$3,$J28,0) | AQ28: =IF($E28=AQ$3,$G28,0)-IF($H28=AQ$3,$J28,0) | AR28: =IF($E28=AR$3,$G28,0)-IF($H28=AR$3,$J28,0) | AS28: =IF($E28=AS$3,$G28,0)-IF($H28=AS$3,$J28,0) | AT28: =IF($E28=AT$3,$G28,0)-IF($H28=AT$3,$J28,0) | AU28: =IF($E28=AU$3,$G28,0)-IF($H28=AU$3,$J28,0) | AV28: =IF($E28=AV$3,$G28,0)-IF($H28=AV$3,$J28,0) | AW28: =IF($E28=AW$3,$G28,0)-IF($H28=AW$3,$J28,0) | ... BK28: =IF($E28=BK$3,$G28,0)-IF($H28=BK$3,$J28,0) | BL28: =-IF($E28=BL$3,$G28,0)+IF($H28=BL$3,$J28,0) | BM28: =-IF($E28=BM$3,$G28,0)+IF($H28=BM$3,$J28,0) | BN28: =-IF($E28=BN$3,$G28,0)+IF($H28=BN$3,$J28,0) | BO28: =-IF($E28=BO$3,$G28,0)+IF($H28=BO$3,$J28,0) | BP28: =-IF($E28=BP$3,$G28,0)+IF($H28=BP$3,$J28,0) | BQ28: =-IF($E28=BQ$3,$G28,0)+IF($H28=BQ$3,$J28,0) | BR28: =-IF($E28=BR$3,$G28,0)+IF($H28=BR$3,$J28,0) | BS28: =-IF($E28=BS$3,$G28,0)+IF($H28=BS$3,$J28,0) | BT28: =-IF($E28=BT$3,$G28,0)+IF($H28=BT$3,$J28,0) | BU28: =+G28-J28 | BV28: =-IF($E28=BV$3,$G28,0)+IF($H28=BV$3,$J28,0)
B29: 1 | C29: 18 | D29: エポス Github | E29: 525 | F29: =IF(E29="","",IF(ISNA(VLOOKUP(E29,科目コード表!$C$4:$D$67,2,FALSE)),"該当科目なし",VLOOKUP(E29,科目コード表!$C$4:$D$67,2,FALSE))) | G29: 1813 | I29: =IF(H29="","",IF(ISNA(VLOOKUP(H29,科目コード表!$C$4:$D$67,2,FALSE)),"該当科目なし",VLOOKUP(H29,科目コード表!$C$4:$D$67,2,FALSE))) | L29: =IF($E29=L$3,$G29,0)-IF($H29=L$3,$J29,0) | M29: =IF($E29=M$3,$G29,0)-IF($H29=M$3,$J29,0) | N29: =IF($E29=N$3,$G29,0)-IF($H29=N$3,$J29,0) | O29: =IF($E29=O$3,$G29,0)-IF($H29=O$3,$J29,0) | P29: =IF($E29=P$3,$G29,0)-IF($H29=P$3,$J29,0) | Q29: =IF($E29=Q$3,$G29,0)-IF($H29=Q$3,$J29,0) | R29: =IF($E29=R$3,$G29,0)-IF($H29=R$3,$J29,0) | S29: =IF($E29=S$3,$G29,0)-IF($H29=S$3,$J29,0) | ... AL29: =IF($E29=AL$3,$G29,0)-IF($H29=AL$3,$J29,0) | AM29: =-IF($E29=AM$3,$G29,0)+IF($H29=AM$3,$J29,0) | AN29: =-IF($E29=AN$3,$G29,0)+IF($H29=AN$3,$J29,0) | AO29: =-IF($E29=AO$3,$G29,0)+IF($H29=AO$3,$J29,0) | AP29: =IF($E29=AP$3,$G29,0)-IF($H29=AP$3,$J29,0) | AQ29: =IF($E29=AQ$3,$G29,0)-IF($H29=AQ$3,$J29,0) | AR29: =IF($E29=AR$3,$G29,0)-IF($H29=AR$3,$J29,0) | AS29: =IF($E29=AS$3,$G29,0)-IF($H29=AS$3,$J29,0) | AT29: =IF($E29=AT$3,$G29,0)-IF($H29=AT$3,$J29,0) | AU29: =IF($E29=AU$3,$G29,0)-IF($H29=AU$3,$J29,0) | AV29: =IF($E29=AV$3,$G29,0)-IF($H29=AV$3,$J29,0) | AW29: =IF($E29=AW$3,$G29,0)-IF($H29=AW$3,$J29,0) | ... BK29: =IF($E29=BK$3,$G29,0)-IF($H29=BK$3,$J29,0) | BL29: =-IF($E29=BL$3,$G29,0)+IF($H29=BL$3,$J29,0) | BM29: =-IF($E29=BM$3,$G29,0)+IF($H29=BM$3,$J29,0) | BN29: =-IF($E29=BN$3,$G29,0)+IF($H29=BN$3,$J29,0) | BO29: =-IF($E29=BO$3,$G29,0)+IF($H29=BO$3,$J29,0) | BP29: =-IF($E29=BP$3,$G29,0)+IF($H29=BP$3,$J29,0) | BQ29: =-IF($E29=BQ$3,$G29,0)+IF($H29=BQ$3,$J29,0) | BR29: =-IF($E29=BR$3,$G29,0)+IF($H29=BR$3,$J29,0) | BS29: =-IF($E29=BS$3,$G29,0)+IF($H29=BS$3,$J29,0) | BT29: =-IF($E29=BT$3,$G29,0)+IF($H29=BT$3,$J29,0) | BU29: =+G29-J29 | BV29: =-IF($E29=BV$3,$G29,0)+IF($H29=BV$3,$J29,0)
B30: 1 | C30: 19 | D30: エポス ガソリン代 | E30: 523 | F30: =IF(E30="","",IF(ISNA(VLOOKUP(E30,科目コード表!$C$4:$D$67,2,FALSE)),"該当科目なし",VLOOKUP(E30,科目コード表!$C$4:$D$67,2,FALSE))) | G30: 3097 | I30: =IF(H30="","",IF(ISNA(VLOOKUP(H30,科目コード表!$C$4:$D$67,2,FALSE)),"該当科目なし",VLOOKUP(H30,科目コード表!$C$4:$D$67,2,FALSE))) | L30: =IF($E30=L$3,$G30,0)-IF($H30=L$3,$J30,0) | M30: =IF($E30=M$3,$G30,0)-IF($H30=M$3,$J30,0) | N30: =IF($E30=N$3,$G30,0)-IF($H30=N$3,$J30,0) | O30: =IF($E30=O$3,$G30,0)-IF($H30=O$3,$J30,0) | P30: =IF($E30=P$3,$G30,0)-IF($H30=P$3,$J30,0) | Q30: =IF($E30=Q$3,$G30,0)-IF($H30=Q$3,$J30,0) | R30: =IF($E30=R$3,$G30,0)-IF($H30=R$3,$J30,0) | S30: =IF($E30=S$3,$G30,0)-IF($H30=S$3,$J30,0) | ... AL30: =IF($E30=AL$3,$G30,0)-IF($H30=AL$3,$J30,0) | AM30: =-IF($E30=AM$3,$G30,0)+IF($H30=AM$3,$J30,0) | AN30: =-IF($E30=AN$3,$G30,0)+IF($H30=AN$3,$J30,0) | AO30: =-IF($E30=AO$3,$G30,0)+IF($H30=AO$3,$J30,0) | AP30: =IF($E30=AP$3,$G30,0)-IF($H30=AP$3,$J30,0) | AQ30: =IF($E30=AQ$3,$G30,0)-IF($H30=AQ$3,$J30,0) | AR30: =IF($E30=AR$3,$G30,0)-IF($H30=AR$3,$J30,0) | AS30: =IF($E30=AS$3,$G30,0)-IF($H30=AS$3,$J30,0) | AT30: =IF($E30=AT$3,$G30,0)-IF($H30=AT$3,$J30,0) | AU30: =IF($E30=AU$3,$G30,0)-IF($H30=AU$3,$J30,0) | AV30: =IF($E30=AV$3,$G30,0)-IF($H30=AV$3,$J30,0) | AW30: =IF($E30=AW$3,$G30,0)-IF($H30=AW$3,$J30,0) | ... BK30: =IF($E30=BK$3,$G30,0)-IF($H30=BK$3,$J30,0) | BL30: =-IF($E30=BL$3,$G30,0)+IF($H30=BL$3,$J30,0) | BM30: =-IF($E30=BM$3,$G30,0)+IF($H30=BM$3,$J30,0) | BN30: =-IF($E30=BN$3,$G30,0)+IF($H30=BN$3,$J30,0) | BO30: =-IF($E30=BO$3,$G30,0)+IF($H30=BO$3,$J30,0) | BP30: =-IF($E30=BP$3,$G30,0)+IF($H30=BP$3,$J30,0) | BQ30: =-IF($E30=BQ$3,$G30,0)+IF($H30=BQ$3,$J30,0) | BR30: =-IF($E30=BR$3,$G30,0)+IF($H30=BR$3,$J30,0) | BS30: =-IF($E30=BS$3,$G30,0)+IF($H30=BS$3,$J30,0) | BT30: =-IF($E30=BT$3,$G30,0)+IF($H30=BT$3,$J30,0) | BU30: =+G30-J30 | BV30: =-IF($E30=BV$3,$G30,0)+IF($H30=BV$3,$J30,0)
B31: 1 | C31: 20 | D31: エポス Microsoft | E31: 525 | F31: =IF(E31="","",IF(ISNA(VLOOKUP(E31,科目コード表!$C$4:$D$67,2,FALSE)),"該当科目なし",VLOOKUP(E31,科目コード表!$C$4:$D$67,2,FALSE))) | G31: 2856 | I31: =IF(H31="","",IF(ISNA(VLOOKUP(H31,科目コード表!$C$4:$D$67,2,FALSE)),"該当科目なし",VLOOKUP(H31,科目コード表!$C$4:$D$67,2,FALSE))) | L31: =IF($E31=L$3,$G31,0)-IF($H31=L$3,$J31,0) | M31: =IF($E31=M$3,$G31,0)-IF($H31=M$3,$J31,0) | N31: =IF($E31=N$3,$G31,0)-IF($H31=N$3,$J31,0) | O31: =IF($E31=O$3,$G31,0)-IF($H31=O$3,$J31,0) | P31: =IF($E31=P$3,$G31,0)-IF($H31=P$3,$J31,0) | Q31: =IF($E31=Q$3,$G31,0)-IF($H31=Q$3,$J31,0) | R31: =IF($E31=R$3,$G31,0)-IF($H31=R$3,$J31,0) | S31: =IF($E31=S$3,$G31,0)-IF($H31=S$3,$J31,0) | ... AL31: =IF($E31=AL$3,$G31,0)-IF($H31=AL$3,$J31,0) | AM31: =-IF($E31=AM$3,$G31,0)+IF($H31=AM$3,$J31,0) | AN31: =-IF($E31=AN$3,$G31,0)+IF($H31=AN$3,$J31,0) | AO31: =-IF($E31=AO$3,$G31,0)+IF($H31=AO$3,$J31,0) | AP31: =IF($E31=AP$3,$G31,0)-IF($H31=AP$3,$J31,0) | AQ31: =IF($E31=AQ$3,$G31,0)-IF($H31=AQ$3,$J31,0) | AR31: =IF($E31=AR$3,$G31,0)-IF($H31=AR$3,$J31,0) | AS31: =IF($E31=AS$3,$G31,0)-IF($H31=AS$3,$J31,0) | AT31: =IF($E31=AT$3,$G31,0)-IF($H31=AT$3,$J31,0) | AU31: =IF($E31=AU$3,$G31,0)-IF($H31=AU$3,$J31,0) | AV31: =IF($E31=AV$3,$G31,0)-IF($H31=AV$3,$J31,0) | AW31: =IF($E31=AW$3,$G31,0)-IF($H31=AW$3,$J31,0) | ... BK31: =IF($E31=BK$3,$G31,0)-IF($H31=BK$3,$J31,0) | BL31: =-IF($E31=BL$3,$G31,0)+IF($H31=BL$3,$J31,0) | BM31: =-IF($E31=BM$3,$G31,0)+IF($H31=BM$3,$J31,0) | BN31: =-IF($E31=BN$3,$G31,0)+IF($H31=BN$3,$J31,0) | BO31: =-IF($E31=BO$3,$G31,0)+IF($H31=BO$3,$J31,0) | BP31: =-IF($E31=BP$3,$G31,0)+IF($H31=BP$3,$J31,0) | BQ31: =-IF($E31=BQ$3,$G31,0)+IF($H31=BQ$3,$J31,0) | BR31: =-IF($E31=BR$3,$G31,0)+IF($H31=BR$3,$J31,0) | BS31: =-IF($E31=BS$3,$G31,0)+IF($H31=BS$3,$J31,0) | BT31: =-IF($E31=BT$3,$G31,0)+IF($H31=BT$3,$J31,0) | BU31: =+G31-J31 | BV31: =-IF($E31=BV$3,$G31,0)+IF($H31=BV$3,$J31,0)
B32: 1 | C32: 21 | D32: ドアプロテクター | E32: 523 | F32: =IF(E32="","",IF(ISNA(VLOOKUP(E32,科目コード表!$C$4:$D$67,2,FALSE)),"該当科目なし",VLOOKUP(E32,科目コード表!$C$4:$D$67,2,FALSE))) | G32: 859 | I32: =IF(H32="","",IF(ISNA(VLOOKUP(H32,科目コード表!$C$4:$D$67,2,FALSE)),"該当科目なし",VLOOKUP(H32,科目コード表!$C$4:$D$67,2,FALSE))) | L32: =IF($E32=L$3,$G32,0)-IF($H32=L$3,$J32,0) | M32: =IF($E32=M$3,$G32,0)-IF($H32=M$3,$J32,0) | N32: =IF($E32=N$3,$G32,0)-IF($H32=N$3,$J32,0) | O32: =IF($E32=O$3,$G32,0)-IF($H32=O$3,$J32,0) | P32: =IF($E32=P$3,$G32,0)-IF($H32=P$3,$J32,0) | Q32: =IF($E32=Q$3,$G32,0)-IF($H32=Q$3,$J32,0) | R32: =IF($E32=R$3,$G32,0)-IF($H32=R$3,$J32,0) | S32: =IF($E32=S$3,$G32,0)-IF($H32=S$3,$J32,0) | ... AL32: =IF($E32=AL$3,$G32,0)-IF($H32=AL$3,$J32,0) | AM32: =-IF($E32=AM$3,$G32,0)+IF($H32=AM$3,$J32,0) | AN32: =-IF($E32=AN$3,$G32,0)+IF($H32=AN$3,$J32,0) | AO32: =-IF($E32=AO$3,$G32,0)+IF($H32=AO$3,$J32,0) | AP32: =IF($E32=AP$3,$G32,0)-IF($H32=AP$3,$J32,0) | AQ32: =IF($E32=AQ$3,$G32,0)-IF($H32=AQ$3,$J32,0) | AR32: =IF($E32=AR$3,$G32,0)-IF($H32=AR$3,$J32,0) | AS32: =IF($E32=AS$3,$G32,0)-IF($H32=AS$3,$J32,0) | AT32: =IF($E32=AT$3,$G32,0)-IF($H32=AT$3,$J32,0) | AU32: =IF($E32=AU$3,$G32,0)-IF($H32=AU$3,$J32,0) | AV32: =IF($E32=AV$3,$G32,0)-IF($H32=AV$3,$J32,0) | AW32: =IF($E32=AW$3,$G32,0)-IF($H32=AW$3,$J32,0) | ... BK32: =IF($E32=BK$3,$G32,0)-IF($H32=BK$3,$J32,0) | BL32: =-IF($E32=BL$3,$G32,0)+IF($H32=BL$3,$J32,0) | BM32: =-IF($E32=BM$3,$G32,0)+IF($H32=BM$3,$J32,0) | BN32: =-IF($E32=BN$3,$G32,0)+IF($H32=BN$3,$J32,0) | BO32: =-IF($E32=BO$3,$G32,0)+IF($H32=BO$3,$J32,0) | BP32: =-IF($E32=BP$3,$G32,0)+IF($H32=BP$3,$J32,0) | BQ32: =-IF($E32=BQ$3,$G32,0)+IF($H32=BQ$3,$J32,0) | BR32: =-IF($E32=BR$3,$G32,0)+IF($H32=BR$3,$J32,0) | BS32: =-IF($E32=BS$3,$G32,0)+IF($H32=BS$3,$J32,0) | BT32: =-IF($E32=BT$3,$G32,0)+IF($H32=BT$3,$J32,0) | BU32: =+G32-J32 | BV32: =-IF($E32=BV$3,$G32,0)+IF($H32=BV$3,$J32,0)
B33: 1 | C33: 21 | D33: Bluetooth 5.4 対応 USB | E33: 514 | F33: =IF(E33="","",IF(ISNA(VLOOKUP(E33,科目コード表!$C$4:$D$67,2,FALSE)),"該当科目なし",VLOOKUP(E33,科目コード表!$C$4:$D$67,2,FALSE))) | G33: 1190 | I33: =IF(H33="","",IF(ISNA(VLOOKUP(H33,科目コード表!$C$4:$D$67,2,FALSE)),"該当科目なし",VLOOKUP(H33,科目コード表!$C$4:$D$67,2,FALSE))) | L33: =IF($E33=L$3,$G33,0)-IF($H33=L$3,$J33,0) | M33: =IF($E33=M$3,$G33,0)-IF($H33=M$3,$J33,0) | N33: =IF($E33=N$3,$G33,0)-IF($H33=N$3,$J33,0) | O33: =IF($E33=O$3,$G33,0)-IF($H33=O$3,$J33,0) | P33: =IF($E33=P$3,$G33,0)-IF($H33=P$3,$J33,0) | Q33: =IF($E33=Q$3,$G33,0)-IF($H33=Q$3,$J33,0) | R33: =IF($E33=R$3,$G33,0)-IF($H33=R$3,$J33,0) | S33: =IF($E33=S$3,$G33,0)-IF($H33=S$3,$J33,0) | ... AL33: =IF($E33=AL$3,$G33,0)-IF($H33=AL$3,$J33,0) | AM33: =-IF($E33=AM$3,$G33,0)+IF($H33=AM$3,$J33,0) | AN33: =-IF($E33=AN$3,$G33,0)+IF($H33=AN$3,$J33,0) | AO33: =-IF($E33=AO$3,$G33,0)+IF($H33=AO$3,$J33,0) | AP33: =IF($E33=AP$3,$G33,0)-IF($H33=AP$3,$J33,0) | AQ33: =IF($E33=AQ$3,$G33,0)-IF($H33=AQ$3,$J33,0) | AR33: =IF($E33=AR$3,$G33,0)-IF($H33=AR$3,$J33,0) | AS33: =IF($E33=AS$3,$G33,0)-IF($H33=AS$3,$J33,0) | AT33: =IF($E33=AT$3,$G33,0)-IF($H33=AT$3,$J33,0) | AU33: =IF($E33=AU$3,$G33,0)-IF($H33=AU$3,$J33,0) | AV33: =IF($E33=AV$3,$G33,0)-IF($H33=AV$3,$J33,0) | AW33: =IF($E33=AW$3,$G33,0)-IF($H33=AW$3,$J33,0) | ... BK33: =IF($E33=BK$3,$G33,0)-IF($H33=BK$3,$J33,0) | BL33: =-IF($E33=BL$3,$G33,0)+IF($H33=BL$3,$J33,0) | BM33: =-IF($E33=BM$3,$G33,0)+IF($H33=BM$3,$J33,0) | BN33: =-IF($E33=BN$3,$G33,0)+IF($H33=BN$3,$J33,0) | BO33: =-IF($E33=BO$3,$G33,0)+IF($H33=BO$3,$J33,0) | BP33: =-IF($E33=BP$3,$G33,0)+IF($H33=BP$3,$J33,0) | BQ33: =-IF($E33=BQ$3,$G33,0)+IF($H33=BQ$3,$J33,0) | BR33: =-IF($E33=BR$3,$G33,0)+IF($H33=BR$3,$J33,0) | BS33: =-IF($E33=BS$3,$G33,0)+IF($H33=BS$3,$J33,0) | BT33: =-IF($E33=BT$3,$G33,0)+IF($H33=BT$3,$J33,0) | BU33: =+G33-J33 | BV33: =-IF($E33=BV$3,$G33,0)+IF($H33=BV$3,$J33,0)
B34: 1 | C34: 22 | D34: トランクネット | E34: 523 | F34: =IF(E34="","",IF(ISNA(VLOOKUP(E34,科目コード表!$C$4:$D$67,2,FALSE)),"該当科目なし",VLOOKUP(E34,科目コード表!$C$4:$D$67,2,FALSE))) | G34: 999 | I34: =IF(H34="","",IF(ISNA(VLOOKUP(H34,科目コード表!$C$4:$D$67,2,FALSE)),"該当科目なし",VLOOKUP(H34,科目コード表!$C$4:$D$67,2,FALSE))) | L34: =IF($E34=L$3,$G34,0)-IF($H34=L$3,$J34,0) | M34: =IF($E34=M$3,$G34,0)-IF($H34=M$3,$J34,0) | N34: =IF($E34=N$3,$G34,0)-IF($H34=N$3,$J34,0) | O34: =IF($E34=O$3,$G34,0)-IF($H34=O$3,$J34,0) | P34: =IF($E34=P$3,$G34,0)-IF($H34=P$3,$J34,0) | Q34: =IF($E34=Q$3,$G34,0)-IF($H34=Q$3,$J34,0) | R34: =IF($E34=R$3,$G34,0)-IF($H34=R$3,$J34,0) | S34: =IF($E34=S$3,$G34,0)-IF($H34=S$3,$J34,0) | ... AL34: =IF($E34=AL$3,$G34,0)-IF($H34=AL$3,$J34,0) | AM34: =-IF($E34=AM$3,$G34,0)+IF($H34=AM$3,$J34,0) | AN34: =-IF($E34=AN$3,$G34,0)+IF($H34=AN$3,$J34,0) | AO34: =-IF($E34=AO$3,$G34,0)+IF($H34=AO$3,$J34,0) | AP34: =IF($E34=AP$3,$G34,0)-IF($H34=AP$3,$J34,0) | AQ34: =IF($E34=AQ$3,$G34,0)-IF($H34=AQ$3,$J34,0) | AR34: =IF($E34=AR$3,$G34,0)-IF($H34=AR$3,$J34,0) | AS34: =IF($E34=AS$3,$G34,0)-IF($H34=AS$3,$J34,0) | AT34: =IF($E34=AT$3,$G34,0)-IF($H34=AT$3,$J34,0) | AU34: =IF($E34=AU$3,$G34,0)-IF($H34=AU$3,$J34,0) | AV34: =IF($E34=AV$3,$G34,0)-IF($H34=AV$3,$J34,0) | AW34: =IF($E34=AW$3,$G34,0)-IF($H34=AW$3,$J34,0) | ... BK34: =IF($E34=BK$3,$G34,0)-IF($H34=BK$3,$J34,0) | BL34: =-IF($E34=BL$3,$G34,0)+IF($H34=BL$3,$J34,0) | BM34: =-IF($E34=BM$3,$G34,0)+IF($H34=BM$3,$J34,0) | BN34: =-IF($E34=BN$3,$G34,0)+IF($H34=BN$3,$J34,0) | BO34: =-IF($E34=BO$3,$G34,0)+IF($H34=BO$3,$J34,0) | BP34: =-IF($E34=BP$3,$G34,0)+IF($H34=BP$3,$J34,0) | BQ34: =-IF($E34=BQ$3,$G34,0)+IF($H34=BQ$3,$J34,0) | BR34: =-IF($E34=BR$3,$G34,0)+IF($H34=BR$3,$J34,0) | BS34: =-IF($E34=BS$3,$G34,0)+IF($H34=BS$3,$J34,0) | BT34: =-IF($E34=BT$3,$G34,0)+IF($H34=BT$3,$J34,0) | BU34: =+G34-J34 | BV34: =-IF($E34=BV$3,$G34,0)+IF($H34=BV$3,$J34,0)
B35: 1 | C35: 22 | D35: 荷掛けフック | E35: 523 | F35: =IF(E35="","",IF(ISNA(VLOOKUP(E35,科目コード表!$C$4:$D$67,2,FALSE)),"該当科目なし",VLOOKUP(E35,科目コード表!$C$4:$D$67,2,FALSE))) | G35: 849 | I35: =IF(H35="","",IF(ISNA(VLOOKUP(H35,科目コード表!$C$4:$D$67,2,FALSE)),"該当科目なし",VLOOKUP(H35,科目コード表!$C$4:$D$67,2,FALSE))) | L35: =IF($E35=L$3,$G35,0)-IF($H35=L$3,$J35,0) | M35: =IF($E35=M$3,$G35,0)-IF($H35=M$3,$J35,0) | N35: =IF($E35=N$3,$G35,0)-IF($H35=N$3,$J35,0) | O35: =IF($E35=O$3,$G35,0)-IF($H35=O$3,$J35,0) | P35: =IF($E35=P$3,$G35,0)-IF($H35=P$3,$J35,0) | Q35: =IF($E35=Q$3,$G35,0)-IF($H35=Q$3,$J35,0) | R35: =IF($E35=R$3,$G35,0)-IF($H35=R$3,$J35,0) | S35: =IF($E35=S$3,$G35,0)-IF($H35=S$3,$J35,0) | ... AL35: =IF($E35=AL$3,$G35,0)-IF($H35=AL$3,$J35,0) | AM35: =-IF($E35=AM$3,$G35,0)+IF($H35=AM$3,$J35,0) | AN35: =-IF($E35=AN$3,$G35,0)+IF($H35=AN$3,$J35,0) | AO35: =-IF($E35=AO$3,$G35,0)+IF($H35=AO$3,$J35,0) | AP35: =IF($E35=AP$3,$G35,0)-IF($H35=AP$3,$J35,0) | AQ35: =IF($E35=AQ$3,$G35,0)-IF($H35=AQ$3,$J35,0) | AR35: =IF($E35=AR$3,$G35,0)-IF($H35=AR$3,$J35,0) | AS35: =IF($E35=AS$3,$G35,0)-IF($H35=AS$3,$J35,0) | AT35: =IF($E35=AT$3,$G35,0)-IF($H35=AT$3,$J35,0) | AU35: =IF($E35=AU$3,$G35,0)-IF($H35=AU$3,$J35,0) | AV35: =IF($E35=AV$3,$G35,0)-IF($H35=AV$3,$J35,0) | AW35: =IF($E35=AW$3,$G35,0)-IF($H35=AW$3,$J35,0) | ... BK35: =IF($E35=BK$3,$G35,0)-IF($H35=BK$3,$J35,0) | BL35: =-IF($E35=BL$3,$G35,0)+IF($H35=BL$3,$J35,0) | BM35: =-IF($E35=BM$3,$G35,0)+IF($H35=BM$3,$J35,0) | BN35: =-IF($E35=BN$3,$G35,0)+IF($H35=BN$3,$J35,0) | BO35: =-IF($E35=BO$3,$G35,0)+IF($H35=BO$3,$J35,0) | BP35: =-IF($E35=BP$3,$G35,0)+IF($H35=BP$3,$J35,0) | BQ35: =-IF($E35=BQ$3,$G35,0)+IF($H35=BQ$3,$J35,0) | BR35: =-IF($E35=BR$3,$G35,0)+IF($H35=BR$3,$J35,0) | BS35: =-IF($E35=BS$3,$G35,0)+IF($H35=BS$3,$J35,0) | BT35: =-IF($E35=BT$3,$G35,0)+IF($H35=BT$3,$J35,0) | BU35: =+G35-J35 | BV35: =-IF($E35=BV$3,$G35,0)+IF($H35=BV$3,$J35,0)
